Workbook

Sheet Summary
A1: 205 Pawnee Street — Outdoor Entertainment Area (Patio + Shed Roof + Screened Enclosure + Wood-Burning Fireplace) | J1: Project Totals
J2: Labor Cost | K2: =SUM(B11:B40) -> 13652.66
A3: Project | B3: Outdoor entertainment area over existing paver/fire-pit area. Built on v3 TAKE-OFF STANDARD; 2026 national-avg retail (confirm local). Rate Set A cost/burden - FIXED scope vs stated TOTAL INVESTMENT $57,745. DEMO: pavers ~12.5x23.5 + existing fire pit + cut/remove ~3x3 concrete at fire-pit area (1 12-yd dumpster + up to 1 haul-off given). CONCRETE: excavate + ~4 yd gravel + forms + std reinforcement + 4" broom patio ~294 SF + 3x3 infill at removed fire pit + control joints + edge hand-grading. ROOF: shed-style over ~294 SF + TIE INTO EXISTING ROOF (ledger and/or beam connections at home + roof-to-wall/roof-to-roof flashing) + rafters per span/load + vertical posts to approved bearing + blocking/bracing/connectors + sheathing + synthetic underlayment + ASPHALT SHINGLES matched most-similar to existing + metal flashing at intersections/valleys/penetrations + pitch/drainage away. SCREENED ENCLOSURE: ~2' KNEE WALLS along perimeter + WHITE VINYL finish at knee walls + screen framing between posts + screening tensioned + trim + 1 screen door opening + door w/ hardware ($125). WOOD-BURNING OUTDOOR FIREPLACE (~72" wide): final height/depth/config/firebox/chimney/finish coordinated per selected design - scope allows approved MASONRY, FRAMED, or MANUFACTURED system - CARRIED ON MANUFACTURED WB OUTDOOR SYSTEM BASIS (scope: fireplace pricing + scope DEPENDENT on final selected system - re-price at selection). Includes: footing/structural support per design + fire-rated materials + firebox + smoke chamber + flue liner + CHIMNEY to required termination height above roofline (10-3-2) + spark arrestor + cap + flashing/weatherproofing at ROOF PENETRATION + fire-rated substrate + customer-selected VENEER ($5/SF, ~150 SF) + HEARTH ($5/SF, ~24 SF, floor-height or raised lip per code) + MANTEL ($1,000, non-combustible or wood if clearances achieved). ELECTRICAL: electric-fireplace circuit/fixture REMOVED per scope; remaining language = install work "AS SPECIFICALLY LISTED" - NOTHING IS LISTED (no fan/lights/outlets anywhere in scope) - minimal coordination carry only + CRITICAL FLAG: screened porch w/ zero electrical = near-certain expectation gap - resolve before contract. PERMITS $0 - scope excludes unless listed (FLAG: roof tie-in + fireplace/chimney + solid-fuel appliance typically require permits/inspection; fireplace details subject to inspection-authority approval per scope). ASSUMES: existing roof/wall framing + bearing suitable; standard soil. EXCLUDED: engineering/drawings/specialty fireplace design/specialty permitting, gas/propane/appliance connections, decorative concrete, rock/buried-beyond/groundwater/utilities/fill/retaining, drainage/landscaping/sod/irrigation/yard restoration, concealed conditions (CO). Cost basis; compare to $57,745. | J3: Material Cost | K3: =SUM(C11:C40) -> 13809.91
A4: Source Scope | B4: 205_Pawnee_Street_-_Proposal.txt | J4: Equipment Cost | K4: =SUM(D11:D40) -> 535
A5: Template Anchor | B5: Basement_Remodel_Breakdown_Locked_Template_v2.xlsx | J5: Grand Total | K5: =SUM(E11:E40) -> 27997.57
A6: Overall Footprint SF | B6: 294
A7: Ceiling Height | B7: 1
A8: Note | B8: Use this workbook as a locked template. Populate detail rows only; preserve formulas, tabs, and section order.
J9: Sold for: | K9: 57745
A10: Section | B10: Labor Cost | C10: Material Cost | D10: Equipment Cost | E10: Section Total | F10: Labor Hours | J10: COG's | K10: =K5 -> 27997.57
A11: GC + PM Coordination (No Permits - Flag) | B11: =SUMIF(Labor_Detail!$A:$A,A11,Labor_Detail!$E:$E) -> 1309.46 | C11: =SUMIF(Material_Detail!$A:$A,A11,Material_Detail!$H:$H) -> 185 | D11: =SUMIF(Equipment_Detail!$A:$A,A11,Equipment_Detail!$F:$F) -> 0 | E11: =SUM(B11:D11) -> 1494.46 | F11: =SUMIF(Labor_Detail!$A:$A,A11,Labor_Detail!$C:$C) -> 30
A12: Demolition (Pavers 294 SF + Fire Pit + 3x3 Cut) | B12: =SUMIF(Labor_Detail!$A:$A,A12,Labor_Detail!$E:$E) -> 679 | C12: =SUMIF(Material_Detail!$A:$A,A12,Material_Detail!$H:$H) -> 185 | D12: =SUMIF(Equipment_Detail!$A:$A,A12,Equipment_Detail!$F:$F) -> 250 | E12: =SUM(B12:D12) -> 1114 | F12: =SUMIF(Labor_Detail!$A:$A,A12,Labor_Detail!$C:$C) -> 20 | J12: Projected GP | K12: =K9 - K10 -> 29747.43
A13: Concrete Patio (294 SF + 3x3 Infill, 4" Broom) | B13: =SUMIF(Labor_Detail!$A:$A,A13,Labor_Detail!$E:$E) -> 1436 | C13: =SUMIF(Material_Detail!$A:$A,A13,Material_Detail!$H:$H) -> 1468 | D13: =SUMIF(Equipment_Detail!$A:$A,A13,Equipment_Detail!$F:$F) -> 285 | E13: =SUM(B13:D13) -> 3189 | F13: =SUMIF(Labor_Detail!$A:$A,A13,Labor_Detail!$C:$C) -> 42 | J13: GP % | K13: =K12/K9 -> 0.51515161
A14: Roof Structure (12.5x23.5 Shed + Tie-In + Posts) | B14: =SUMIF(Labor_Detail!$A:$A,A14,Labor_Detail!$E:$E) -> 2406.8 | C14: =SUMIF(Material_Detail!$A:$A,A14,Material_Detail!$H:$H) -> 1983.31 | D14: =SUMIF(Equipment_Detail!$A:$A,A14,Equipment_Detail!$F:$F) -> 0 | E14: =SUM(B14:D14) -> 4390.11 | F14: =SUMIF(Labor_Detail!$A:$A,A14,Labor_Detail!$C:$C) -> 70
A15: Shingle Roofing + Flashing (Match Existing) | B15: =SUMIF(Labor_Detail!$A:$A,A15,Labor_Detail!$E:$E) -> 814.8 | C15: =SUMIF(Material_Detail!$A:$A,A15,Material_Detail!$H:$H) -> 839.3 | D15: =SUMIF(Equipment_Detail!$A:$A,A15,Equipment_Detail!$F:$F) -> 0 | E15: =SUM(B15:D15) -> 1654.1 | F15: =SUMIF(Labor_Detail!$A:$A,A15,Labor_Detail!$C:$C) -> 24
A16: Screened Enclosure (2' Knee Walls + Door $125) | B16: =SUMIF(Labor_Detail!$A:$A,A16,Labor_Detail!$E:$E) -> 1629.6 | C16: =SUMIF(Material_Detail!$A:$A,A16,Material_Detail!$H:$H) -> 1713.05 | D16: =SUMIF(Equipment_Detail!$A:$A,A16,Equipment_Detail!$F:$F) -> 0 | E16: =SUM(B16:D16) -> 3342.65 | F16: =SUMIF(Labor_Detail!$A:$A,A16,Labor_Detail!$C:$C) -> 48
A17: WB Fireplace Structure (Firebox + Flue + Chimney) | B17: =SUMIF(Labor_Detail!$A:$A,A17,Labor_Detail!$E:$E) -> 3367.5 | C17: =SUMIF(Material_Detail!$A:$A,A17,Material_Detail!$H:$H) -> 4974.25 | D17: =SUMIF(Equipment_Detail!$A:$A,A17,Equipment_Detail!$F:$F) -> 0 | E17: =SUM(B17:D17) -> 8341.75 | F17: =SUMIF(Labor_Detail!$A:$A,A17,Labor_Detail!$C:$C) -> 98
A18: Fireplace Finish (Veneer/Hearth $5/SF + Mantel $1,000) | B18: =SUMIF(Labor_Detail!$A:$A,A18,Labor_Detail!$E:$E) -> 1358 | C18: =SUMIF(Material_Detail!$A:$A,A18,Material_Detail!$H:$H) -> 2302 | D18: =SUMIF(Equipment_Detail!$A:$A,A18,Equipment_Detail!$F:$F) -> 0 | E18: =SUM(B18:D18) -> 3660 | F18: =SUMIF(Labor_Detail!$A:$A,A18,Labor_Detail!$C:$C) -> 40
A19: Electrical (As Specifically Listed - NONE Listed - Flag) | B19: =SUMIF(Labor_Detail!$A:$A,A19,Labor_Detail!$E:$E) -> 234 | C19: =SUMIF(Material_Detail!$A:$A,A19,Material_Detail!$H:$H) -> 95 | D19: =SUMIF(Equipment_Detail!$A:$A,A19,Equipment_Detail!$F:$F) -> 0 | E19: =SUM(B19:D19) -> 329 | F19: =SUMIF(Labor_Detail!$A:$A,A19,Labor_Detail!$C:$C) -> 6
A20: Final Install + Cleanup (1 Dumpster + Haul) | B20: =SUMIF(Labor_Detail!$A:$A,A20,Labor_Detail!$E:$E) -> 417.5 | C20: =SUMIF(Material_Detail!$A:$A,A20,Material_Detail!$H:$H) -> 65 | D20: =SUMIF(Equipment_Detail!$A:$A,A20,Equipment_Detail!$F:$F) -> 0 | E20: =SUM(B20:D20) -> 482.5 | F20: =SUMIF(Labor_Detail!$A:$A,A20,Labor_Detail!$C:$C) -> 12
A21: Not Applicable | B21: =SUMIF(Labor_Detail!$A:$A,A21,Labor_Detail!$E:$E) -> 0 | C21: =SUMIF(Material_Detail!$A:$A,A21,Material_Detail!$H:$H) -> 0 | D21: =SUMIF(Equipment_Detail!$A:$A,A21,Equipment_Detail!$F:$F) -> 0 | E21: =SUM(B21:D21) -> 0 | F21: =SUMIF(Labor_Detail!$A:$A,A21,Labor_Detail!$C:$C) -> 0
A22: Not Applicable | B22: =SUMIF(Labor_Detail!$A:$A,A22,Labor_Detail!$E:$E) -> 0 | C22: =SUMIF(Material_Detail!$A:$A,A22,Material_Detail!$H:$H) -> 0 | D22: =SUMIF(Equipment_Detail!$A:$A,A22,Equipment_Detail!$F:$F) -> 0 | E22: =SUM(B22:D22) -> 0 | F22: =SUMIF(Labor_Detail!$A:$A,A22,Labor_Detail!$C:$C) -> 0
A23: Not Applicable | B23: =SUMIF(Labor_Detail!$A:$A,A23,Labor_Detail!$E:$E) -> 0 | C23: =SUMIF(Material_Detail!$A:$A,A23,Material_Detail!$H:$H) -> 0 | D23: =SUMIF(Equipment_Detail!$A:$A,A23,Equipment_Detail!$F:$F) -> 0 | E23: =SUM(B23:D23) -> 0 | F23: =SUMIF(Labor_Detail!$A:$A,A23,Labor_Detail!$C:$C) -> 0
A24: Not Applicable | B24: =SUMIF(Labor_Detail!$A:$A,A24,Labor_Detail!$E:$E) -> 0 | C24: =SUMIF(Material_Detail!$A:$A,A24,Material_Detail!$H:$H) -> 0 | D24: =SUMIF(Equipment_Detail!$A:$A,A24,Equipment_Detail!$F:$F) -> 0 | E24: =SUM(B24:D24) -> 0 | F24: =SUMIF(Labor_Detail!$A:$A,A24,Labor_Detail!$C:$C) -> 0
A25: Not Applicable | B25: =SUMIF(Labor_Detail!$A:$A,A25,Labor_Detail!$E:$E) -> 0 | C25: =SUMIF(Material_Detail!$A:$A,A25,Material_Detail!$H:$H) -> 0 | D25: =SUMIF(Equipment_Detail!$A:$A,A25,Equipment_Detail!$F:$F) -> 0 | E25: =SUM(B25:D25) -> 0 | F25: =SUMIF(Labor_Detail!$A:$A,A25,Labor_Detail!$C:$C) -> 0
... A40: Not Applicable | B40: =SUMIF(Labor_Detail!$A:$A,A40,Labor_Detail!$E:$E) -> 0 | C40: =SUMIF(Material_Detail!$A:$A,A40,Material_Detail!$H:$H) -> 0 | D40: =SUMIF(Equipment_Detail!$A:$A,A40,Equipment_Detail!$F:$F) -> 0 | E40: =SUM(B40:D40) -> 0 | F40: =SUMIF(Labor_Detail!$A:$A,A40,Labor_Detail!$C:$C) -> 0
A41: TOTALS | B41: =SUM(B11:B40) -> 13652.66 | C41: =SUM(C11:C40) -> 13809.91 | D41: =SUM(D11:D40) -> 535 | E41: =SUM(E11:E40) -> 27997.57 | F41: =SUM(F11:F40) -> 390

Sheet Labor_Detail
A1: Section | B1: Trade Role | C1: Hours | D1: Rate | E1: Labor Cost | F1: Notes | G1: Rate Category
A2: GC + PM Coordination (No Permits - Flag) | B2: Project Manager | C2: 18 | D2: {=IF(OR($A2="",$G2=""),"",_xlfn.XLOOKUP($G2,Labor_Rates!$A$3:$A$7,Labor_Rates!$B$3:$B$7,""))} -> 47.87 | E2: =IF(OR($A2="",$C2="",$D2=""),"",$C2*$D2) -> 861.66 | F2: PM ~5-6 wk: fireplace design/selection coordination (system + veneer + hearth + mantel + clearances + inspection-authority approval per scope) + shingle match + selections + scheduling. NO permits carried (flag). | G2: Project Manager
A3: GC + PM Coordination (No Permits - Flag) | B3: Team Lead | C3: 8 | D3: {=IF(OR($A3="",$G3=""),"",_xlfn.XLOOKUP($G3,Labor_Rates!$A$3:$A$7,Labor_Rates!$B$3:$B$7,""))} -> 39 | E3: =IF(OR($A3="",$C3="",$D3=""),"",$C3*$D3) -> 312 | F3: TL field lead: demo/concrete/roof/screen/fireplace phases. | G3: Team Lead
A4: GC + PM Coordination (No Permits - Flag) | B4: General Labor | C4: 4 | D4: {=IF(OR($A4="",$G4=""),"",_xlfn.XLOOKUP($G4,Labor_Rates!$A$3:$A$7,Labor_Rates!$B$3:$B$7,""))} -> 33.95 | E4: =IF(OR($A4="",$C4="",$D4=""),"",$C4*$D4) -> 135.8 | F4: Staging + debris areas + access protection. | G4: General Labor
A5: Demolition (Pavers 294 SF + Fire Pit + 3x3 Cut) | B5: General Labor | C5: 20 | D5: {=IF(OR($A5="",$G5=""),"",_xlfn.XLOOKUP($G5,Labor_Rates!$A$3:$A$7,Labor_Rates!$B$3:$B$7,""))} -> 33.95 | E5: =IF(OR($A5="",$C5="",$D5=""),"",$C5*$D5) -> 679 | F5: Demo pavers ~294 SF + existing fire pit + saw-cut/remove 3x3 concrete + load dumpster + dispose. | G5: General Labor
A6: Concrete Patio (294 SF + 3x3 Infill, 4" Broom) | B6: Team Lead | C6: 2 | D6: {=IF(OR($A6="",$G6=""),"",_xlfn.XLOOKUP($G6,Labor_Rates!$A$3:$A$7,Labor_Rates!$B$3:$B$7,""))} -> 39 | E6: =IF(OR($A6="",$C6="",$D6=""),"",$C6*$D6) -> 78 | F6: Patio layout + fireplace footing coordination (pour together). | G6: Team Lead
A7: Concrete Patio (294 SF + 3x3 Infill, 4" Broom) | B7: General Labor | C7: 40 | D7: {=IF(OR($A7="",$G7=""),"",_xlfn.XLOOKUP($G7,Labor_Rates!$A$3:$A$7,Labor_Rates!$B$3:$B$7,""))} -> 33.95 | E7: =IF(OR($A7="",$C7="",$D7=""),"",$C7*$D7) -> 1358 | F7: Excavate + 4 yd gravel + forms + reinforcement + pour/finish 4" broom ~294 SF + 3x3 infill + control joints + edge hand-grading. Coordinate fireplace footing/thickened area in pour. | G7: General Labor
A8: Roof Structure (12.5x23.5 Shed + Tie-In + Posts) | B8: Team Lead | C8: 6 | D8: {=IF(OR($A8="",$G8=""),"",_xlfn.XLOOKUP($G8,Labor_Rates!$A$3:$A$7,Labor_Rates!$B$3:$B$7,""))} -> 39 | E8: =IF(OR($A8="",$C8="",$D8=""),"",$C8*$D8) -> 234 | F8: Roof tie-in lead: ledger/beam connections + bearing points + pitch/drainage. | G8: Team Lead
A9: Roof Structure (12.5x23.5 Shed + Tie-In + Posts) | B9: General Labor | C9: 64 | D9: {=IF(OR($A9="",$G9=""),"",_xlfn.XLOOKUP($G9,Labor_Rates!$A$3:$A$7,Labor_Rates!$B$3:$B$7,""))} -> 33.95 | E9: =IF(OR($A9="",$C9="",$D9=""),"",$C9*$D9) -> 2172.8 | F9: Shed roof ~294 SF: structural ledger/beam at home + vertical posts to approved bearing + rafters per span/load + blocking/bracing/connectors + sheathing + roof-to-wall/roof-to-roof flashing prep + chimney-penetration framing. | G9: General Labor
A10: Shingle Roofing + Flashing (Match Existing) | B10: General Labor | C10: 24 | D10: {=IF(OR($A10="",$G10=""),"",_xlfn.XLOOKUP($G10,Labor_Rates!$A$3:$A$7,Labor_Rates!$B$3:$B$7,""))} -> 33.95 | E10: =IF(OR($A10="",$C10="",$D10=""),"",$C10*$D10) -> 814.8 | F10: Synthetic underlayment + asphalt shingles (~3.3 sq, matched to existing) + metal flashing at intersections/valleys/penetrations + tie-in shingle weave/step flashing. | G10: General Labor
A11: Screened Enclosure (2' Knee Walls + Door $125) | B11: General Labor | C11: 48 | D11: {=IF(OR($A11="",$G11=""),"",_xlfn.XLOOKUP($G11,Labor_Rates!$A$3:$A$7,Labor_Rates!$B$3:$B$7,""))} -> 33.95 | E11: =IF(OR($A11="",$C11="",$D11=""),"",$C11*$D11) -> 1629.6 | F11: Screened enclosure: frame ~2' knee walls along perimeter + WHITE VINYL finish at knee walls + screen framing between posts + screening installed/tensioned + trim + frame door opening + screen door w/ hardware. | G11: General Labor
A12: WB Fireplace Structure (Firebox + Flue + Chimney) | B12: Team Lead | C12: 8 | D12: {=IF(OR($A12="",$G12=""),"",_xlfn.XLOOKUP($G12,Labor_Rates!$A$3:$A$7,Labor_Rates!$B$3:$B$7,""))} -> 39 | E12: =IF(OR($A12="",$C12="",$D12=""),"",$C12*$D12) -> 312 | F12: Fireplace lead: system layout + clearances + chimney height (10-3-2 above roofline) + inspection coordination. | G12: Team Lead
A13: WB Fireplace Structure (Firebox + Flue + Chimney) | B13: General Labor | C13: 90 | D13: {=IF(OR($A13="",$G13=""),"",_xlfn.XLOOKUP($G13,Labor_Rates!$A$3:$A$7,Labor_Rates!$B$3:$B$7,""))} -> 33.95 | E13: =IF(OR($A13="",$C13="",$D13=""),"",$C13*$D13) -> 3055.5 | F13: Construct WB fireplace (~72" wide, manufactured-system basis): footing/structural support + frame/CMU structure + fire-rated substrate + set firebox + smoke chamber + flue liner + chimney system to required termination + spark arrestor + cap + flashing/weatherproofing at roof penetration. | G13: General Labor
... A37: Not Applicable | B37: General Labor | C37: 0 | D37: {=IF(OR($A37="",$G37=""),"",_xlfn.XLOOKUP($G37,Labor_Rates!$A$3:$A$7,Labor_Rates!$B$3:$B$7,""))} -> 33.95 | E37: =IF(OR($A37="",$C37="",$D37=""),"",$C37*$D37) -> 0 | F37: Not Applicable | G37: General Labor
D38: {=IF(OR($A38="",$G38=""),"",_xlfn.XLOOKUP($G38,Labor_Rates!$A$3:$A$7,Labor_Rates!$B$3:$B$7,""))} | E38: =IF(OR($A38="",$C38="",$D38=""),"",$C38*$D38)
D39: {=IF(OR($A39="",$G39=""),"",_xlfn.XLOOKUP($G39,Labor_Rates!$A$3:$A$7,Labor_Rates!$B$3:$B$7,""))} | E39: =IF(OR($A39="",$C39="",$D39=""),"",$C39*$D39)
D40: {=IF(OR($A40="",$G40=""),"",_xlfn.XLOOKUP($G40,Labor_Rates!$A$3:$A$7,Labor_Rates!$B$3:$B$7,""))} | E40: =IF(OR($A40="",$C40="",$D40=""),"",$C40*$D40)
D41: {=IF(OR($A41="",$G41=""),"",_xlfn.XLOOKUP($G41,Labor_Rates!$A$3:$A$7,Labor_Rates!$B$3:$B$7,""))} | E41: =IF(OR($A41="",$C41="",$D41=""),"",$C41*$D41)
D42: {=IF(OR($A42="",$G42=""),"",_xlfn.XLOOKUP($G42,Labor_Rates!$A$3:$A$7,Labor_Rates!$B$3:$B$7,""))} | E42: =IF(OR($A42="",$C42="",$D42=""),"",$C42*$D42)
D43: {=IF(OR($A43="",$G43=""),"",_xlfn.XLOOKUP($G43,Labor_Rates!$A$3:$A$7,Labor_Rates!$B$3:$B$7,""))} | E43: =IF(OR($A43="",$C43="",$D43=""),"",$C43*$D43)
D44: {=IF(OR($A44="",$G44=""),"",_xlfn.XLOOKUP($G44,Labor_Rates!$A$3:$A$7,Labor_Rates!$B$3:$B$7,""))} | E44: =IF(OR($A44="",$C44="",$D44=""),"",$C44*$D44)
D45: {=IF(OR($A45="",$G45=""),"",_xlfn.XLOOKUP($G45,Labor_Rates!$A$3:$A$7,Labor_Rates!$B$3:$B$7,""))} | E45: =IF(OR($A45="",$C45="",$D45=""),"",$C45*$D45)
D46: {=IF(OR($A46="",$G46=""),"",_xlfn.XLOOKUP($G46,Labor_Rates!$A$3:$A$7,Labor_Rates!$B$3:$B$7,""))} | E46: =IF(OR($A46="",$C46="",$D46=""),"",$C46*$D46)
D47: {=IF(OR($A47="",$G47=""),"",_xlfn.XLOOKUP($G47,Labor_Rates!$A$3:$A$7,Labor_Rates!$B$3:$B$7,""))} | E47: =IF(OR($A47="",$C47="",$D47=""),"",$C47*$D47)
D48: {=IF(OR($A48="",$G48=""),"",_xlfn.XLOOKUP($G48,Labor_Rates!$A$3:$A$7,Labor_Rates!$B$3:$B$7,""))} | E48: =IF(OR($A48="",$C48="",$D48=""),"",$C48*$D48)
D49: {=IF(OR($A49="",$G49=""),"",_xlfn.XLOOKUP($G49,Labor_Rates!$A$3:$A$7,Labor_Rates!$B$3:$B$7,""))} | E49: =IF(OR($A49="",$C49="",$D49=""),"",$C49*$D49)
... D300: {=IF(OR($A300="",$G300=""),"",_xlfn.XLOOKUP($G300,Labor_Rates!$A$3:$A$7,Labor_Rates!$B$3:$B$7,""))} | E300: =IF(OR($A300="",$C300="",$D300=""),"",$C300*$D300)

Sheet Material_Detail
A1: Section | B1: Material | C1: Description | D1: Quantity | E1: Unit | F1: Unit Cost | G1: Waste Factor | H1: Line Total | I1: Notes / Pricing Source
A2: GC + PM Coordination (No Permits - Flag) | B2: Protection + consumables | C2: Staging + protection. NO permit allowance (scope excludes - FLAG). | D2: 1 | E2: lot | F2: 185 | G2: 0 | H2: =IF(OR($A2="",$D2=""),"",$D2*$F2*(1+$G2)) -> 185 | I2: 2026 natl-avg retail; confirm local.
A3: Demolition (Pavers 294 SF + Fire Pit + 3x3 Cut) | B3: Demo consumables | C3: Saw blades + breaker bits + bags (pavers + fire pit + 3x3 cut) | D3: 1 | E3: lot | F3: 185 | G3: 0 | H3: =IF(OR($A3="",$D3=""),"",$D3*$F3*(1+$G3)) -> 185 | I3: 2026 natl-avg retail; confirm local.
A4: Concrete Patio (294 SF + 3x3 Infill, 4" Broom) | B4: Gravel base (4 yd) | C4: Per scope | D4: 4 | E4: yd | F4: 45 | G4: 0 | H4: =IF(OR($A4="",$D4=""),"",$D4*$F4*(1+$G4)) -> 180 | I4: 2026 natl-avg retail; confirm local.
A5: Concrete Patio (294 SF + 3x3 Infill, 4" Broom) | B5: Forms + stakes | C5: Form lumber + stakes (294 SF + infill) | D5: 1 | E5: lot | F5: 185 | G5: 0 | H5: =IF(OR($A5="",$D5=""),"",$D5*$F5*(1+$G5)) -> 185 | I5: 2026 natl-avg retail; confirm local.
A6: Concrete Patio (294 SF + 3x3 Infill, 4" Broom) | B6: Reinforcement | C6: Wire mesh/rebar standard + fireplace footing rebar | D6: 1 | E6: lot | F6: 225 | G6: 0 | H6: =IF(OR($A6="",$D6=""),"",$D6*$F6*(1+$G6)) -> 225 | I6: 2026 natl-avg retail; confirm local.
A7: Concrete Patio (294 SF + 3x3 Infill, 4" Broom) | B7: Ready-mix concrete (4.2 yd) | C7: 294 SF + 9 SF infill @ 4" + fireplace footing thickening | D7: 4.2 | E7: yd | F7: 165 | G7: 0 | H7: =IF(OR($A7="",$D7=""),"",$D7*$F7*(1+$G7)) -> 693 | I7: 2026 natl-avg retail; confirm local.
A8: Concrete Patio (294 SF + 3x3 Infill, 4" Broom) | B8: Concrete delivery fee | C8: Truck delivery | D8: 1 | E8: lot | F8: 185 | G8: 0 | H8: =IF(OR($A8="",$D8=""),"",$D8*$F8*(1+$G8)) -> 185 | I8: 2026 natl-avg retail; confirm local.
A9: Roof Structure (12.5x23.5 Shed + Tie-In + Posts) | B9: Structural ledger + beams | C9: Ledger/beam connections at home + carrying beams | D9: 1 | E9: lot | F9: 585 | G9: 0.05 | H9: =IF(OR($A9="",$D9=""),"",$D9*$F9*(1+$G9)) -> 614.25 | I9: 2026 natl-avg retail; confirm local.
A10: Roof Structure (12.5x23.5 Shed + Tie-In + Posts) | B10: 6x6 PT posts (~5) | C10: Vertical supports to bearing | D10: 5 | E10: ea | F10: 48 | G10: 0.05 | H10: =IF(OR($A10="",$D10=""),"",$D10*$F10*(1+$G10)) -> 252 | I10: 2026 natl-avg retail; confirm local.
A11: Roof Structure (12.5x23.5 Shed + Tie-In + Posts) | B11: 2x8 rafters (~19) | C11: Per span/load, 12.5' + overhang | D11: 19 | E11: ea | F11: 28 | G11: 0.08 | H11: =IF(OR($A11="",$D11=""),"",$D11*$F11*(1+$G11)) -> 574.56 | I11: 2026 natl-avg retail; confirm local.
A12: Roof Structure (12.5x23.5 Shed + Tie-In + Posts) | B12: Blocking + bracing + connectors | C12: Blocking + bracing + hurricane ties + hardware + exterior fasteners | D12: 1 | E12: lot | F12: 385 | G12: 0 | H12: =IF(OR($A12="",$D12=""),"",$D12*$F12*(1+$G12)) -> 385 | I12: 2026 natl-avg retail; confirm local.
A13: Roof Structure (12.5x23.5 Shed + Tie-In + Posts) | B13: Roof sheathing (~10 sheets) | C13: 7/16 OSB | D13: 10 | E13: sheet | F13: 15 | G13: 0.05 | H13: =IF(OR($A13="",$D13=""),"",$D13*$F13*(1+$G13)) -> 157.5 | I13: 2026 natl-avg retail; confirm local.
... A32: Final Install + Cleanup (1 Dumpster + Haul) | B32: Cleanup supplies | C32: Bags + consumables | D32: 1 | E32: lot | F32: 65 | G32: 0 | H32: =IF(OR($A32="",$D32=""),"",$D32*$F32*(1+$G32)) -> 65 | I32: 2026 natl-avg retail; confirm local.
A33: Not Applicable | B33: Not Applicable | C33: Not Applicable | D33: 1 | E33: lot | F33: 0 | G33: 0 | H33: =IF(OR($A33="",$D33=""),"",$D33*$F33*(1+$G33)) -> 0
A34: Not Applicable | B34: Not Applicable | C34: Not Applicable | D34: 1 | E34: lot | F34: 0 | G34: 0 | H34: =IF(OR($A34="",$D34=""),"",$D34*$F34*(1+$G34)) -> 0
A35: Not Applicable | B35: Not Applicable | C35: Not Applicable | D35: 1 | E35: lot | F35: 0 | G35: 0 | H35: =IF(OR($A35="",$D35=""),"",$D35*$F35*(1+$G35)) -> 0
A36: Not Applicable | B36: Not Applicable | C36: Not Applicable | D36: 1 | E36: lot | F36: 0 | G36: 0 | H36: =IF(OR($A36="",$D36=""),"",$D36*$F36*(1+$G36)) -> 0
A37: Not Applicable | B37: Not Applicable | C37: Not Applicable | D37: 1 | E37: lot | F37: 0 | G37: 0 | H37: =IF(OR($A37="",$D37=""),"",$D37*$F37*(1+$G37)) -> 0
A38: Not Applicable | B38: Not Applicable | C38: Not Applicable | D38: 1 | E38: lot | F38: 0 | G38: 0 | H38: =IF(OR($A38="",$D38=""),"",$D38*$F38*(1+$G38)) -> 0
A39: Not Applicable | B39: Not Applicable | C39: Not Applicable | D39: 1 | E39: lot | F39: 0 | G39: 0 | H39: =IF(OR($A39="",$D39=""),"",$D39*$F39*(1+$G39)) -> 0
A40: Not Applicable | B40: Not Applicable | C40: Not Applicable | D40: 1 | E40: lot | F40: 0 | G40: 0 | H40: =IF(OR($A40="",$D40=""),"",$D40*$F40*(1+$G40)) -> 0
A41: Not Applicable | B41: Not Applicable | C41: Not Applicable | D41: 1 | E41: lot | F41: 0 | G41: 0 | H41: =IF(OR($A41="",$D41=""),"",$D41*$F41*(1+$G41)) -> 0
A42: Not Applicable | B42: Not Applicable | C42: Not Applicable | D42: 1 | E42: lot | F42: 0 | G42: 0 | H42: =IF(OR($A42="",$D42=""),"",$D42*$F42*(1+$G42)) -> 0
A43: Not Applicable | B43: Not Applicable | C43: Not Applicable | D43: 1 | E43: lot | F43: 0 | G43: 0 | H43: =IF(OR($A43="",$D43=""),"",$D43*$F43*(1+$G43)) -> 0
A44: Not Applicable | B44: Not Applicable | C44: Not Applicable | D44: 1 | E44: lot | F44: 0 | G44: 0 | H44: =IF(OR($A44="",$D44=""),"",$D44*$F44*(1+$G44)) -> 0
... A52: Not Applicable | B52: Not Applicable | C52: Not Applicable | D52: 1 | E52: lot | F52: 0 | G52: 0 | H52: =IF(OR($A52="",$D52=""),"",$D52*$F52*(1+$G52)) -> 0
H53: =IF(OR($A53="",$D53="",$F53=""),"",$D53*$F53*(1+$G53))
H54: =IF(OR($A54="",$D54="",$F54=""),"",$D54*$F54*(1+$G54))
H55: =IF(OR($A55="",$D55="",$F55=""),"",$D55*$F55*(1+$G55))
H56: =IF(OR($A56="",$D56="",$F56=""),"",$D56*$F56*(1+$G56))
H57: =IF(OR($A57="",$D57="",$F57=""),"",$D57*$F57*(1+$G57))
H58: =IF(OR($A58="",$D58="",$F58=""),"",$D58*$F58*(1+$G58))
H59: =IF(OR($A59="",$D59="",$F59=""),"",$D59*$F59*(1+$G59))
H60: =IF(OR($A60="",$D60="",$F60=""),"",$D60*$F60*(1+$G60))
H61: =IF(OR($A61="",$D61="",$F61=""),"",$D61*$F61*(1+$G61))
H62: =IF(OR($A62="",$D62="",$F62=""),"",$D62*$F62*(1+$G62))
H63: =IF(OR($A63="",$D63="",$F63=""),"",$D63*$F63*(1+$G63))
H64: =IF(OR($A64="",$D64="",$F64=""),"",$D64*$F64*(1+$G64))
... H400: =IF(OR($A400="",$D400="",$F400=""),"",$D400*$F400*(1+$G400))

Sheet Equipment_Detail
A1: Section | B1: Equipment or Misc Item | C1: Quantity | D1: Unit | E1: Unit Cost | F1: Line Total | G1: Notes
A2: Demolition (Pavers 294 SF + Fire Pit + 3x3 Cut) | B2: 12-yd dumpster + 1 haul-off | C2: 1 | D2: lot | E2: 250 | F2: =IF(OR($A2="",$C2=""),"",$C2*$E2) -> 250 | G2: Per scope: 1 dumpster + up to 1 haul-off. Pavers + fire pit = heavy.
A3: Concrete Patio (294 SF + 3x3 Infill, 4" Broom) | B3: Mini-excavator/skid rental | C3: 1 | D3: day | E3: 285 | F3: =IF(OR($A3="",$C3=""),"",$C3*$E3) -> 285 | G3: Excavation + gravel.
A4: GC + PM Coordination (No Permits - Flag) | B4: Portable toilet rental | C4: 0 | D4: month | E4: 145 | F4: =IF(OR($A4="",$C4=""),"",$C4*$E4) -> 0 | G4: ~5-6 wk build.
A5: Not Applicable | B5: Not Applicable | C5: 0 | D5: lot | E5: 0 | F5: =IF(OR($A5="",$C5=""),"",$C5*$E5) -> 0
A6: Not Applicable | B6: Not Applicable | C6: 0 | D6: lot | E6: 0 | F6: =IF(OR($A6="",$C6=""),"",$C6*$E6) -> 0
A7: Not Applicable | B7: Not Applicable | C7: 0 | D7: lot | E7: 0 | F7: =IF(OR($A7="",$C7=""),"",$C7*$E7) -> 0
A8: Not Applicable | B8: Not Applicable | C8: 0 | D8: lot | E8: 0 | F8: =IF(OR($A8="",$C8=""),"",$C8*$E8) -> 0
A9: Not Applicable | B9: Not Applicable | C9: 0 | D9: lot | E9: 0 | F9: =IF(OR($A9="",$C9=""),"",$C9*$E9) -> 0
A10: Not Applicable | B10: Not Applicable | C10: 0 | D10: lot | E10: 0 | F10: =IF(OR($A10="",$C10=""),"",$C10*$E10) -> 0
A11: Not Applicable | B11: Not Applicable | C11: 0 | D11: lot | E11: 0 | F11: =IF(OR($A11="",$C11=""),"",$C11*$E11) -> 0
A12: Not Applicable | B12: Not Applicable | C12: 0 | D12: lot | E12: 0 | F12: =IF(OR($A12="",$C12=""),"",$C12*$E12) -> 0
A13: Not Applicable | B13: Not Applicable | C13: 0 | D13: lot | E13: 0 | F13: =IF(OR($A13="",$C13=""),"",$C13*$E13) -> 0
A14: Not Applicable | B14: Not Applicable | C14: 0 | D14: lot | E14: 0 | F14: =IF(OR($A14="",$C14=""),"",$C14*$E14) -> 0
A15: Not Applicable | B15: Not Applicable | C15: 0 | D15: lot | E15: 0 | F15: =IF(OR($A15="",$C15=""),"",$C15*$E15) -> 0
A16: Not Applicable | B16: Not Applicable | C16: 0 | D16: lot | E16: 0 | F16: =IF(OR($A16="",$C16=""),"",$C16*$E16) -> 0
... A24: Not Applicable | B24: Not Applicable | C24: 0 | D24: lot | E24: 0 | F24: =IF(OR($A24="",$C24=""),"",$C24*$E24) -> 0
F25: =IF(OR($A25="",$C25="",$E25=""),"",$C25*$E25)
F26: =IF(OR($A26="",$C26="",$E26=""),"",$C26*$E26)
F27: =IF(OR($A27="",$C27="",$E27=""),"",$C27*$E27)
F28: =IF(OR($A28="",$C28="",$E28=""),"",$C28*$E28)
F29: =IF(OR($A29="",$C29="",$E29=""),"",$C29*$E29)
F30: =IF(OR($A30="",$C30="",$E30=""),"",$C30*$E30)
F31: =IF(OR($A31="",$C31="",$E31=""),"",$C31*$E31)
F32: =IF(OR($A32="",$C32="",$E32=""),"",$C32*$E32)
F33: =IF(OR($A33="",$C33="",$E33=""),"",$C33*$E33)
F34: =IF(OR($A34="",$C34="",$E34=""),"",$C34*$E34)
F35: =IF(OR($A35="",$C35="",$E35=""),"",$C35*$E35)
F36: =IF(OR($A36="",$C36="",$E36=""),"",$C36*$E36)
... F200: =IF(OR($A200="",$C200="",$E200=""),"",$C200*$E200)

Sheet PM_Notes
A1: Section | B1: Risk Type | C1: Issue | D1: PM Recommendation
A2: Electrical scope is EMPTY - resolve before contract | B2: CRITICAL | C2: Electric fireplace circuit/fixture REMOVED per scope; remaining language = install "as specifically listed" - and NOTHING is listed. No fan, no lights, no outlets anywhere. | D2: A screened entertainment porch with a fireplace and ZERO electrical is a near-certain expectation gap (same lesson as the Sugarwood upper enclosure). Ask the customer NOW: fan? lights? GFCI outlets? Each is a cheap add while framing is open and a painful one after the roof/screens close. Get either the additions priced or the zero-electrical intent acknowledged in writing.
A3: Fireplace priced on MANUFACTURED system - scope protects the selection | B3: CRITICAL | C3: Scope allows masonry, framed, or manufactured WB system + says fireplace pricing/scope DEPENDENT on final selected system. Carried: manufactured firebox/flue/chimney (~$3,500 system) + structure + veneer/hearth/mantel allowances. | D3: A full site-built masonry fireplace would add $4-8K+ materials + significant labor vs the manufactured basis - the scope language already makes that a re-price, which is good protection. Lock the system selection EARLY (it drives the footing, the chimney chase framing, and the roof penetration). Final details subject to inspection-authority approval per scope.
A4: Chimney through the new roof = code height + flashing | B4: CRITICAL | C4: Chimney/flue extends to required termination above roofline (10-3-2 rule) + spark arrestor + cap + penetration flashing/weatherproofing. | D4: The chimney height depends on where it lands relative to the NEW shed roof AND the existing house roof - verify the 10-3-2 geometry at layout (termination can end up taller than customers expect visually). The roof penetration flashing is the leak point - storm collar + counter-flash carefully. Wood-burning appliances draw inspector attention; permits excluded = confirm responsibility in writing.
A5: Roof tie-in to existing structure | B5: Coordination | C5: Shed roof ties into existing roof (ledger and/or beam at home + roof-to-wall/roof-to-roof flashing). Existing framing ASSUMED suitable. | D5: Same discipline as Burgie: verify what the ledger lands on + flash the tie-in deliberately. Shingles matched most-similar (aged vs new will show). Concealed conditions at tie-in = CO per scope.
A6: $0 permits - roof + solid-fuel appliance are triggers | B6: CRITICAL | C6: Scope excludes permits/fees/inspections unless listed. New roof structure tied to home + wood-burning fireplace + chimney typically require permits; scope itself references inspection-authority approval for the fireplace. | D6: Confirm permitting responsibility in writing before starting - a solid-fuel fireplace without inspection is a liability + insurance problem for the HOMEOWNER too (worth telling them).
A7: Fireplace footing pours with the patio | B7: Coordination | C7: Footing/structural support per final fireplace design + weight. Carried as thickened area in the patio pour. | D7: Lock the fireplace selection BEFORE the concrete pour - a masonry system may need a deeper/reinforced footing than a manufactured kit. Pouring first + selecting later = saw-cutting your new patio.
A8: Veneer/hearth quantities are planning numbers | B8: Scope Note | C8: ~150 SF veneer + ~24 SF hearth carried @ $5/SF allowances; mantel $1,000 (wood only if clearances achieved). | D8: Final quantities follow the selected design (72" wide x TBD height). Above-allowance materials = CO. Wood mantel clearance per firebox mfr - verify before promising.
A9: Screen system: knee walls + vinyl + door | B9: Scope Note | C9: 2' knee walls w/ white vinyl finish + tensioned screens + trim + 1 door ($125). | D9: Confirm knee-wall runs + door location at layout. $125 door allowance = basic aluminum/wood unit.
A10: Dumpster: pavers + fire pit = heavy loads | B10: Scope Note | C10: 1 12-yd + 1 haul-off given. ~294 SF pavers + masonry fire pit + 3x3 concrete. | D10: Dense demo - load smart. Overage = CO.
A11: Margin healthy on manufactured basis | B11: Coordination | C11: Cost basis ~$29K vs $57,745 = ~50% GM on the manufactured-fireplace basis - above band. | D11: Cushion is real but the fireplace selection is the swing item: full masonry could pull GM back toward ~38-40% (still in band). The scope re-price language is your protection - use it at selection. Outdoor-living + fireplace jobs price well for you, consistent with the bath pattern.

Sheet Assumptions
A1: Category
A2: Project name | B2: 205 Pawnee Street — Outdoor Entertainment Area: 294 SF Patio + Shed Roof + Screened Enclosure + 72" Wood-Burning Fireplace (FIXED SCOPE) | D2: From scope / intake | E2: Metadata
A3: Overall footprint | B3: Tri-Cities Remodeling & Construction Co. — Will Fallon, Elizabethton TN | C3: SF | D3: From intake and scope | E3: Drives flooring, ceiling, production
A4: Ceiling height | B4: Rate Set A cost/burden. Built on v3 TAKE-OFF STANDARD (itemized + 2026 pricing + per-line source + waste). CONFIRM local pricing. | C4: ft | D4: From intake and scope | E4: Drives wall area
A5: Interior wall length | B5: PERMITS $0 - scope EXCLUDES unless listed (FLAG: roof tie-in + wood-burning fireplace/chimney typically require permits + inspection; scope references inspection-authority approval - confirm responsibility in writing). | C5: LF | D5: From intake/drawings or assumptions | E5: Drives framing and two-sided finishes
A6: Exterior wall length | B6: DEMO: pavers ~294 SF + fire pit + 3x3 concrete cut (1 12-yd dumpster + 1 haul-off given - heavy loads). CONCRETE: 4 yd gravel + forms + reinforcement + 4" broom ~294 SF + 3x3 infill + control joints + fireplace footing thickening in pour (LOCK fireplace selection BEFORE pour). | C6: LF | D6: From intake/drawings or assumptions | E6: Drives framing, insulation, one-sided finishes
A7: Finish wall area | B7: ROOF: shed over ~294 SF + tie into existing (ledger/beam + roof-to-wall/roof-to-roof flashing; existing framing ASSUMED suitable) + posts to bearing + rafters per span + sheathing + underlayment + shingles matched most-similar + full flashing + chimney-penetration framing. | C7: SF | D7: Exterior LF×H + Interior LF×H×2 | E7: Drives drywall, paint
A8: Baseboard gross | B8: SCREENED ENCLOSURE: 2' knee walls + WHITE VINYL finish + screen framing/screening tensioned + trim + 1 screen door ($125). | C8: LF | D8: Exterior LF + Interior LF×2 less openings/cabinets | E8: Drives trim
A9: Door count actual | B9: FIREPLACE (~72" wide): carried on MANUFACTURED WB outdoor system basis (~$3,500 firebox/flue/chimney) + structure + fire-rated substrate + chimney to 10-3-2 termination + arrestor/cap + roof-penetration flashing + veneer ~150 SF @ $5/SF + hearth ~24 SF @ $5/SF + mantel $1,000 (wood only if clearances). SCOPE: pricing DEPENDENT on selected system - masonry selection = RE-PRICE (protection language in doc). | C9: ea | D9: From drawings / intake | E9: Drives trim and CO logic
A10: Door count allowed | B10: ELECTRICAL: electric-fireplace items REMOVED; work "as specifically listed" = NOTHING LISTED (no fan/lights/outlets). Minimal carry only. CRITICAL FLAG: resolve fan/light/outlet expectation BEFORE contract (adds cheap while open; painful after screens close). | C10: ea | D10: From contract baseline | E10: Scope alignment
A11: Window count actual | B11: EXCLUDED: engineering/drawings/specialty fireplace design/permitting, gas/propane/appliance connections, decorative concrete, rock/buried-beyond/groundwater/utilities/fill/retaining, drainage/landscaping/sod/irrigation/restoration, concealed conditions (CO). | C11: ea | D11: From drawings / intake | E11: Scope alignment
A12: Window count allowed | B12: Field-verify dims/pitch/tie-in/chimney geometry before ordering. Cost basis vs stated TOTAL INVESTMENT $57,745 (~50% GM on manufactured basis; masonry selection pulls toward ~38-40% - still in band). | C12: ea | D12: From contract baseline | E12: Scope alignment
A13: Tile area | B13: [AI derive] | C13: SF | D13: From bath / scope | E13: Drives tile materials and labor
A14: Production rates used | B14: [AI document] | D14: Required by prompt | E14: Labor realism
A15: Source files | B15: [AI list] | D15: Scope PDF + intake workbook + prompt + template | E15: Audit trail

Sheet Labor_Rates
A1: Editable Labor Rates
A2: Rate Category | B2: Hourly Rate | C2: Used For | D2: Note
A3: General Labor | B3: 33.95 | C3: Laborer, Carpenter, Painter, Drywall, Flooring, Tile, Cabinet install, countertop/template support | D3: Edit B3 only
A4: Team Lead | B4: 39 | C4: Any row marked Team Lead | D4: Edit B4 only
A5: Electrical/HVAC | B5: 39 | C5: Electrician, HVAC Tech, HVAC Helper | D5: Edit B5 only
A6: Plumbing | B6: 33.92 | C6: Plumber | D6: Edit B6 only
A7: Project Manager | B7: 47.87 | C7: Project Manager rows | D7: Edit B7 only
A9: Instructions | B9: Change any rate in column B and all linked labor rows plus summary labor totals will update.
A10: Example | B10: Set General Labor to 42 to update all General Labor rows everywhere in the workbook.

Sheet Template_Guide
A1: Locked Template Guide
A2: Purpose | B2: Use this exact workbook as the anchor template for every basement remodel output.
A3: How to use | B3: 1) Upload this template 2) Upload PM intake/validation workbook 3) Upload scope PDF 4) Upload locked prompt 5) Ask AI to populate THIS workbook only.
A4: Hard rules | B4: Do not rename tabs, do not change summary layout, do not hardcode totals, do not remove labor rate controls.
A5: Auto-create sections | B5: AI must map scope items into the standard sections listed on Section_Master (S11-S40, 30 sections). Unused sections stay in Summary with zero totals; detail tabs only get rows for relevant sections.
A6: Dropdowns | B6: Detail tabs use dropdown lists for Section, Rate Category, Risk Type, and common Units to keep data normalized.
A7: Change order logic | B7: Use PM intake scope-alignment flags to note credit opportunities and change-order risks in PM_Notes.
A8: Best practice | B8: Always upload this template with the prompt so the AI can match structure, formulas, and layout instead of improvising.
A9: Material take-off standard | B9: STANDARD (v3): Material_Detail must be an ITEMIZED QUANTITY TAKE-OFF, not "lot" lines. Break every material into orderable units (sticks/sheets/bundles/rolls/bags/buckets/LF/sq) with a real Quantity, Unit, and Unit Cost. Use current web-searched pricing; cite the source/date in the Notes/Pricing Source column. Apply a per-material Waste Factor (col G). Keep scope ALLOWANCE items at their face value and flag "ALLOWANCE" in Notes. See the TakeOff_Standard tab for the full process, waste-factor convention, and current pricing benchmarks.
A10: Pricing currency | B10: Material unit prices go stale. Re-confirm current pricing each build (web search for the movers: metal roof panels, cabinets, framing lumber, drywall, LVP, siding). All benchmark figures are national-average retail — PMs confirm local Tri-Cities supplier pricing before ordering. Bulk drywall (34+ sheets) typically 10-25% less.
A12: Version | B12: v3 - Added MATERIAL TAKE-OFF STANDARD. Material_Detail is now an itemized quantity take-off (orderable units + current pricing + per-line source + per-material waste). Added TakeOff_Standard tab (process + waste convention + 2026 pricing benchmarks). Expanded Units dropdown. Notes header -> "Notes / Pricing Source". All v2 mechanics, formulas, tab names, cell positions, and section structure UNCHANGED.

Sheet Data_Lists
A1: Sections | B1: Rate Categories | C1: Risk Types | D1: Units | E1: Include?
A2: General Conditions & Project Management | B2: General Labor | C2: Scope Gap | D2: ea | E2: Yes
A3: Selective Demolition | B3: Team Lead | C3: Change Order Risk | D3: lf | E3: No
A4: Framing | B4: Electrical/HVAC | C4: Credit Opportunity | D4: sf
A5: Windows & Exterior Openings | B5: Plumbing | C5: Existing Conditions | D5: sheet
A6: Plumbing & Waste Pump System | B6: Project Manager | C6: Takeoff Assumption | D6: lot
A7: Electrical | C7: Structural Risk | D7: gal
A8: HVAC - 3 Zone Mini Split | C8: Coordination | D8: bag
A9: Insulation & Air Sealing | C9: Sequencing | D9: box
A10: Drywall & Finishing | C10: Production Risk | D10: roll
A11: Suspended Ceiling System | C11: Allowance Risk | D11: set
A12: Interior Doors, Trim & Hardware | D12: pair
A13: Flooring | D13: day
A14: Painting | D14: bucket
A15: Master Bathroom | D15: sq
A16: Kitchen | D16: tube
A17: Cleanup & Closeout | D17: pack
A18: Garage / Conversion Area | D18: pail
A19: Laundry / Pantry / Utility Relocation | D19: bundle
A20: Closets & Storage Build-Out | D20: stick
A21: Concrete Flatwork & Site Work | D21: board
A22: Decking, Landings & Exterior Stairs | D22: allow
A23: Roofing & Flashing
A24: Specialty Finish Area A
A25: Specialty Finish Area B
A26: Specialty Finish Area C
A27: Specialty Finish Area D
A28: Optional Package A
A29: Optional Package B
A30: Optional Package C
A31: Cleanup & Closeout

Sheet Section_Master
A1: Standard Section | B1: Default Include | C1: Use For / Notes
A2: General Conditions & Project Management | B2: Yes | C2: Site setup, PM time, scheduling, protection
A3: Selective Demolition | B3: Yes | C3: Selective demo, removals, disposal, concrete sawcut
A4: Framing | B4: Yes | C4: Exterior/interior walls, soffits, chases, blocking
A5: Windows & Exterior Openings | B5: Yes | C5: New windows, exterior doors, lintels, flashing
A6: Plumbing & Waste Pump System | B6: Yes | C6: Bath, kitchen, laundry, below-slab, ejector/pump
A7: Electrical | B7: Yes | C7: Subpanel, branch circuits, lighting, devices
A8: HVAC - 3 Zone Mini Split | B8: Yes | C8: Mini split or other HVAC equipment and startup
A9: Insulation & Air Sealing | B9: Yes | C9: Batt, foam, air sealing, sound attenuation
A10: Drywall & Finishing | B10: Yes | C10: Wall board, taping, mud, sanding, access panels
A11: Suspended Ceiling System | B11: Yes | C11: Drop ceiling grid, tile, access coordination
A12: Interior Doors, Trim & Hardware | B12: Yes | C12: Interior doors, base, casing, hardware, trim
... A31: Cleanup & Closeout | B31: Yes | C31: Final clean, punch support, closeout, walkthrough

Sheet TakeOff_Standard
A1: Material Take-Off Standard — Tri-Cities Remodeling & Construction Co.
A2: Applies to every estimating workbook built from this template (v3+). This tab travels with the file so the standard is replicable without prior context.
A4: THE STANDARD
A5: Material_Detail is an ITEMIZED QUANTITY TAKE-OFF, not "lot" placeholder lines. Every material is broken into the units a PM would actually order (sticks, sheets, bundles, rolls, bags, buckets, LF, squares), each with a real Quantity, Unit, and Unit Cost. Goal: a PM can order directly off the sheet.
A7: 7-STEP PROCESS
A8: 1. Intake + clarify (billing method, permits, key SF/LF quantities, allowance handling) — same as always.
A9: 2. Map scope to the standard sections (S11-S40). Set capped/limit quantities where scope states limits.
A10: 3. RESEARCH PRICING: web-search current unit prices for the movers (metal roof, cabinets, framing lumber, drywall, LVP, siding, insulation, gutters). Retailer pages hide live prices behind JS — use cost-guide aggregators (homeguide, angi, modernize, thisoldhouse, costflowai) that publish actual figures.
A11: 4. Build the take-off: one Material_Detail row per orderable item. Fill Quantity, Unit, Unit Cost. Put the price source + date in Notes/Pricing Source (e.g. "2026 natl-avg retail; confirm local").
A12: 5. Apply per-material Waste Factor in col G (see convention below). Line Total auto-calcs = Qty x Unit Cost x (1 + Waste).
A13: 6. Keep scope ALLOWANCE items at face value (cabinets, windows, doors, LVP $/SF, fixtures, deep clean). Flag "ALLOWANCE per scope" in Notes. Do NOT itemize inside an allowance.
A14: 7. Validate (0 section-name mismatches, TOTALS row 41), copy to outputs, present, report totals + PM notes + assumptions. Note material total may shift vs a lot-based pass once itemized.
A16: WASTE-FACTOR CONVENTION (col G; editable per line)
A17: Material class | B17: Waste %
A18: Drywall, siding, LVP, decking | B18: 10%
A19: Framing lumber (rafters/joists/studs/plates) | B19: 8%
A20: Sheathing (OSB/ply), roofing panels, trim, insulation | B20: 5%
A21: Cut-up / cathedral / vaulted areas (bump up) | B21: 15-20%
A22: Allowances + fixed/quoted items + fixtures | B22: 0%
A24: ALLOWANCE CONVENTION
A25: Scope-stated allowances are carried at face value as a single line at their $ amount (Unit = "allow" or "ea"/"sf" as appropriate), flagged "ALLOWANCE per scope" in Notes. Examples: cabinets, countertops, windows ($/ea), doors ($/ea), LVP ($/SF), fans/fixtures ($/ea), deep clean. Contractor-selected construction materials (lumber, sheathing, drywall, paint, fasteners, etc.) ARE itemized.
A27: PRICING BENCHMARKS — current as of June 2026
A28: National-average retail (Home Depot / Lowe's / cost-guide data). CONFIRM LOCAL Tri-Cities supplier pricing before ordering. Re-verify each build — these go stale.
A29: Item | B29: Unit | C29: 2026 range | D29: Value to use | E29: Source / note
A30: 1/2" drywall 4x8 standard | B30: sheet | C30: $12-16 | D30: $14 | E30: HomeGuide/costflowai 2026
A31: 1/2" MR (green) board 4x8 | B31: sheet | C31: +25-30% | D31: $18 | E31: costflowai 2026
A32: 5/8" Type X drywall 4x8 | B32: sheet | C32: $13-17 | D32: $15 | E32: homeguide 2026
A33: Joint compound 4.5-gal bucket | B33: bucket | C33: ~$18 | D33: $18 | E33: 1 bucket / 250-300 SF; costflowai
A34: Metal panel, exposed-fastener 26-ga | B34: sq | C34: steel $2-5/SF | D34: $235/sq | E34: Western States/RoofPredict 2026
A35: Metal panel, standing seam | B35: sq | C35: $150-200 mat | D35: re-price | E35: RoofPredict 2026 (if existing is SS)
A36: Metal roof trim/ridge/flashing | B36: % of panel | C36: +25% expo | D36: sep lines | E36: Western States (exposed-fastener)
A37: Synthetic roof underlayment | B37: roll (10 sq) | C37: ~$150-180 | D37: $165 | E37: market 2026
A38: 7/16 OSB sheathing 4x8 | B38: sheet | C38: $10-25 | D38: $15 | E38: BuildShow/Angi 2026
A39: 3/4" T&G OSB subfloor 4x8 | B39: sheet | C39: $50-77 | D39: $38-50 | E39: Angi 2026 (mid-range)
A40: 1/2" CDX plywood 4x8 | B40: sheet | C40: $16-24 | D40: $20 | E40: BuildShow 2026
... A51: PT deck lumber | B51: ea | C51: market | D51: confirm | E51: HD/Lowe's (live price; confirm)
A53: CAVEATS
A54: These are NATIONAL-AVERAGE RETAIL figures. Regional + bulk pricing varies materially. Lock supplier quotes on the high-dollar movers before committing a bid.
A55: On insurance work, take-off quantities are sized to CAPPED scope limits. Concealed conditions beyond a cap = written SUPPLEMENT, not absorbed. The take-off gives the adjuster line-item backup.
A56: Pre-exposure framing counts are estimates sized to the SF caps. Field-verify after tear-off before ordering lumber.
...
