Workbook

Sheet Package Comparison
A1: HOT TUB RESTORATION PACKAGES — MASTER COMPARISON
A2: Each package includes everything in the package before it. Column prices are individual shop pricing; the flat package price is at the bottom.
A4: # | B4: Category | C4: Line Item | D4: Shop Price | E4: BASE Coverage | F4: BASE Value | G4: PREMIUM Coverage | H4: PREMIUM Value | I4: PLATINUM Coverage | J4: PLATINUM Value
A5: BASE RESTORATION — FOUNDATION ITEMS (carried into every package)
A6: 1 | B6: Structural & Frame | C6: Frame Repair | D6: 900 | E6: Included | F6: =D6*1 -> 900 | G6: Included | H6: =D6*1 -> 900 | I6: Included | J6: =D6*1 -> 900
A7: 2 | B7: Electronics - Pumps | C7: Pump Rebuild | D7: 360 | E7: Included | F7: =D7*1 -> 360 | G7: Replaced by Pump Replacement | H7: 0 | I7: Replaced by Pump Replacement | J7: 0
A8: 3 | B8: Electronics - Other | C8: Ozone Generator Installation | D8: 255 | E8: Included | F8: =D8*1 -> 255 | G8: Included | H8: =D8*1 -> 255 | I8: Included | J8: =D8*1 -> 255
A9: 4 | B9: Cleaning | C9: Internal Plumbing Chemical Flush | D9: 450 | E9: Included | F9: =D9*1 -> 450 | G9: Included | H9: =D9*1 -> 450 | I9: Included | J9: =D9*1 -> 450
A10: 5 | B10: Plumbing | C10: Plumbing Pressure Test (45 PSI) | D10: 1200 | E10: Included | F10: =D10*1 -> 1200 | G10: Included | H10: =D10*1 -> 1200 | I10: Included | J10: =D10*1 -> 1200
A11: 6 | B11: Jets | C11: Jet Resealing | D11: 105 | E11: Up to 4 jets | F11: =D11*1 -> 105 | G11: Unlimited jet resealing — Upgrade | H11: =D11*1 -> 105 | I11: Unlimited jet resealing — Upgrade | J11: =D11*1 -> 105
A12: 7 | B12: Trim / Accessories | C12: Headrest Replacement | D12: 45 | E12: Included | F12: =D12*1 -> 45 | G12: Included | H12: =D12*1 -> 45 | I12: Included | J12: =D12*1 -> 45
A13: 8 | B13: Upgrades | C13: Insulation Package | D13: 1000 | E13: Included | F13: =D13*1 -> 1000 | G13: Included | H13: =D13*1 -> 1000 | I13: Included | J13: =D13*1 -> 1000
A14: 9 | B14: Logistics | C14: On-Prop Move with Two Hours | D14: 860 | E14: Included | F14: =D14*1 -> 860 | G14: Included | H14: =D14*1 -> 860 | I14: Included | J14: =D14*1 -> 860
A15: 10 | B15: Plumbing | C15: Union Gasket Replacement | D15: 150 | E15: Included | F15: =D15*1 -> 150 | G15: Included | H15: =D15*1 -> 150 | I15: Included | J15: =D15*1 -> 150
A16: PREMIUM RESTORATION — ADDED ON TOP OF BASE
A17: 11 | B17: Electronics - Pumps | C17: Pump Replacement ($650 per pump) | D17: 650 | E17: — | F17: 0 | G17: 1 pump included — Upgrade | H17: =D17*1 -> 650 | I17: ALL pumps — no per-pump upcharge | J17: =D17*2 -> 1300
A18: 12 | B18: Electronics - Lighting | C18: LED Lighting Upgrade (x16 Sloan modules) | D18: 1360 | E18: — | F18: 0 | G18: Included — Upgrade | H18: =D18*1 -> 1360 | I18: Included — Upgrade | J18: =D18*1 -> 1360
A19: 13 | B19: Shell-Mounted | C19: Shell-Mounted Component Replacement | D19: 920 | E19: — | F19: 0 | G19: Included — Upgrade | H19: =D19*1 -> 920 | I19: Included — Upgrade | J19: =D19*1 -> 920
A20: 14 | B20: Cleaning | C20: Shell Polishing | D20: 620 | E20: — | F20: 0 | G20: Included — Upgrade | H20: =D20*1 -> 620 | I20: Included — Upgrade | J20: =D20*1 -> 620
A21: 15 | B21: Refined Hardware | C21: Hardware Refinishing | D21: 500 | E21: — | F21: 0 | G21: Included — Upgrade | H21: =D21*1 -> 500 | I21: Included — Upgrade | J21: =D21*1 -> 500
A22: 16 | B22: Trim / Accessories | C22: Side Paint & Varnish | D22: 351 | E22: — | F22: 0 | G22: Included — Upgrade | H22: =D22*1 -> 351 | I22: Included — Upgrade | J22: =D22*1 -> 351
A23: 17 | B23: Water Care | C23: FROG Water-Care System | D23: 350 | E23: — | F23: 0 | G23: Included — Upgrade | H23: =D23*1 -> 350 | I23: Included — Upgrade | J23: =D23*1 -> 350
A24: 18 | B24: Upgrades | C24: Rodent Protection Package | D24: 600 | E24: — | F24: 0 | G24: Included | H24: =D24*1 -> 600 | I24: Included | J24: =D24*1 -> 600
A25: 19 | B25: Service | C25: Spa Care Subscription (per month) | D25: 236 | E25: — | F25: 0 | G25: First month included | H25: =D25*1 -> 236 | I25: First 3 months included | J25: =D25*3 -> 708
A26: PLATINUM RESTORATION — ADDED ON TOP OF PREMIUM
A27: 20 | B27: Electronics - Controller | C27: Topside Controller Upgrade (Balboa SpaTouch4 Wi-Fi) | D27: 800 | E27: — | F27: 0 | G27: — | H27: 0 | I27: Included — Platinum Exclusive | J27: =D27*1 -> 800
A28: 21 | B28: Electronics - Spa Pack | C28: Spa Pack Upgrade (Balboa BP7, 4.0/5.5 kW) | D28: 750 | E28: — | F28: 0 | G28: — | H28: 0 | I28: Included — Platinum Exclusive | J28: =D28*1 -> 750
A29: 22 | B29: Electronics - Audio | C29: Stereo Upgrade (marine-grade + subwoofer) | D29: 1368 | E29: — | F29: 0 | G29: — | H29: 0 | I29: Included — Platinum Exclusive | J29: =D29*1 -> 1368
A30: 23 | B30: Electronics - Pumps | C30: Circulation Pump Installation | D30: 400 | E30: — | F30: 0 | G30: — | H30: 0 | I30: Included — Platinum Exclusive | J30: =D30*1 -> 400
A31: 24 | B31: Cover | C31: Custom Spa Cover (double 4 mm vapor barrier) | D31: 890 | E31: — | F31: 0 | G31: — | H31: 0 | I31: Included — Platinum Exclusive | J31: =D31*1 -> 890
A32: 25 | B32: Warranty | C32: Extended Warranty Upgrade (1 year vs 90 days) | D32: 150 | E32: — | F32: 0 | G32: — | H32: 0 | I32: Included — Platinum Exclusive | J32: =D32*1 -> 150
A33: WARRANTY & COVERAGE
B34: Warranty | C34: Full-coverage restoration warranty | D34: Included | E34: 90 days | G34: 90 days | I34: 1 year
C36: PRICE WITHOUT THE RESTORATION PACKAGE (every included job bought individually) | F36: =SUM(F5:F32) -> 5325 | H36: =SUM(H5:H32) -> 10552 | J36: =SUM(J5:J32) -> 16032
C37: Step-up cost vs. the package below | F37: — | H37: =H36-F36 -> 5227 | J37: =J36-H36 -> 5480
A39: CUSTOMER PRICING — FLAT ALL-IN PACKAGE PRICE
C40: PRICE WITH THE RESTORATION PACKAGE | F40: 4100 | H40: 6300 | J40: 8400
C41: Customer savings (without minus with) | F41: =F36-F40 -> 1225 | H41: =H36-H40 -> 4252 | J41: =J36-J40 -> 7632
C42: Savings as % of the without-package price | F42: =(F36-F40)/F36 -> 0.23004695 | H42: =(H36-H40)/H36 -> 0.40295679 | J42: =(J36-J40)/J36 -> 0.4760479
C43: Price step-up vs. the package below | F43: — | H43: =H40-F40 -> 2200 | J43: =J40-H40 -> 2100
...

Sheet Base Breakdown
A1: BASE RESTORATION — LINE-ITEM BREAKDOWN
A2: $4,100 all-in. Essential mechanical and structural renewal. 90-day full-coverage warranty. Round-trip transport included.
A4: # | B4: Category | C4: Line Item | D4: What's Covered | E4: Value
A5: EVERYTHING IN THE BASE PACKAGE
A6: 1 | B6: Structural & Frame | C6: Frame Repair | D6: Included | E6: 900
A7: 2 | B7: Electronics - Pumps | C7: Pump Rebuild | D7: Included | E7: 360
A8: 3 | B8: Electronics - Other | C8: Ozone Generator Installation | D8: Included | E8: 255
A9: 4 | B9: Cleaning | C9: Internal Plumbing Chemical Flush | D9: Included | E9: 450
A10: 5 | B10: Plumbing | C10: Plumbing Pressure Test (45 PSI) | D10: Included | E10: 1200
A11: 6 | B11: Jets | C11: Jet Resealing | D11: Up to 4 jets | E11: 105
A12: 7 | B12: Trim / Accessories | C12: Headrest Replacement | D12: Included | E12: 45
A13: 8 | B13: Upgrades | C13: Insulation Package | D13: Included | E13: 1000
A14: 9 | B14: Logistics | C14: On-Prop Move with Two Hours | D14: Included | E14: 860
A15: 10 | B15: Plumbing | C15: Union Gasket Replacement | D15: Included | E15: 150
D16: Subtotal — Everything In The Base Package | E16: =SUM(E6:E15) -> 5325
D18: PRICE WITHOUT THE RESTORATION PACKAGE | E18: ='Package Comparison'!F36 -> 5325
D19: PRICE WITH THE RESTORATION PACKAGE | E19: ='Package Comparison'!F40 -> 4100
C20: ="("&TEXT('Package Comparison'!F42,"0%")&" off the without-package price)" -> (23% off the without-package price) | D20: YOU SAVE | E20: ='Package Comparison'!F41 -> 1225
D21: Warranty | E21: 90 days
D22: Round-trip transportation | E22: Included

Sheet Premium Breakdown
A1: PREMIUM RESTORATION — LINE-ITEM BREAKDOWN
A2: $6,300 all-in. Everything in Base, with pumps replaced instead of rebuilt, plus cosmetic and comfort upgrades. 90-day warranty.
A4: # | B4: Category | C4: Line Item | D4: What's Covered | E4: Value
A5: CARRIED OVER FROM BASE — all Base work is included
A6: 1 | B6: Structural & Frame | C6: Frame Repair | D6: Included | E6: 900
A7: 2 | B7: Electronics - Other | C7: Ozone Generator Installation | D7: Included | E7: 255
A8: 3 | B8: Cleaning | C8: Internal Plumbing Chemical Flush | D8: Included | E8: 450
A9: 4 | B9: Plumbing | C9: Plumbing Pressure Test (45 PSI) | D9: Included | E9: 1200
A10: 5 | B10: Jets | C10: Jet Resealing | D10: Unlimited jet resealing — Upgrade | E10: 105
A11: 6 | B11: Trim / Accessories | C11: Headrest Replacement | D11: Included | E11: 45
A12: 7 | B12: Upgrades | C12: Insulation Package | D12: Included | E12: 1000
A13: 8 | B13: Logistics | C13: On-Prop Move with Two Hours | D13: Included | E13: 860
A14: 9 | B14: Plumbing | C14: Union Gasket Replacement | D14: Included | E14: 150
D15: Subtotal — Carried Over From Base | E15: =SUM(E6:E14) -> 4965
A16: ADDED AT PREMIUM — new work beyond Base
A17: 10 | B17: Electronics - Pumps | C17: Pump Replacement ($650 per pump) | D17: 1 pump included — Upgrade | E17: 650
A18: 11 | B18: Electronics - Lighting | C18: LED Lighting Upgrade (x16 Sloan modules) | D18: Included — Upgrade | E18: 1360
A19: 12 | B19: Shell-Mounted | C19: Shell-Mounted Component Replacement | D19: Included — Upgrade | E19: 920
A20: 13 | B20: Cleaning | C20: Shell Polishing | D20: Included — Upgrade | E20: 620
A21: 14 | B21: Refined Hardware | C21: Hardware Refinishing | D21: Included — Upgrade | E21: 500
A22: 15 | B22: Trim / Accessories | C22: Side Paint & Varnish | D22: Included — Upgrade | E22: 351
A23: 16 | B23: Water Care | C23: FROG Water-Care System | D23: Included — Upgrade | E23: 350
A24: 17 | B24: Upgrades | C24: Rodent Protection Package | D24: Included | E24: 600
A25: 18 | B25: Service | C25: Spa Care Subscription (per month) | D25: First month included | E25: 236
D26: Subtotal — Added At Premium | E26: =SUM(E17:E25) -> 5587
D28: PRICE WITHOUT THE RESTORATION PACKAGE | E28: ='Package Comparison'!H36 -> 10552
D29: PRICE WITH THE RESTORATION PACKAGE | E29: ='Package Comparison'!H40 -> 6300
C30: ="("&TEXT('Package Comparison'!H42,"0%")&" off the without-package price)" -> (40% off the without-package price) | D30: YOU SAVE | E30: ='Package Comparison'!H41 -> 4252
D31: Warranty | E31: 90 days
D32: Round-trip transportation | E32: Included

Sheet Platinum Breakdown
A1: PLATINUM RESTORATION — LINE-ITEM BREAKDOWN
A2: $8,400 all-in. Everything in Premium, plus the technology, audio, cover and circulation exclusives. 1-year warranty.
A4: # | B4: Category | C4: Line Item | D4: What's Covered | E4: Value
A5: CARRIED OVER FROM BASE — all Base work is included
A6: 1 | B6: Structural & Frame | C6: Frame Repair | D6: Included | E6: 900
A7: 2 | B7: Electronics - Other | C7: Ozone Generator Installation | D7: Included | E7: 255
A8: 3 | B8: Cleaning | C8: Internal Plumbing Chemical Flush | D8: Included | E8: 450
A9: 4 | B9: Plumbing | C9: Plumbing Pressure Test (45 PSI) | D9: Included | E9: 1200
A10: 5 | B10: Jets | C10: Jet Resealing | D10: Unlimited jet resealing — Upgrade | E10: 105
A11: 6 | B11: Trim / Accessories | C11: Headrest Replacement | D11: Included | E11: 45
A12: 7 | B12: Upgrades | C12: Insulation Package | D12: Included | E12: 1000
A13: 8 | B13: Logistics | C13: On-Prop Move with Two Hours | D13: Included | E13: 860
A14: 9 | B14: Plumbing | C14: Union Gasket Replacement | D14: Included | E14: 150
D15: Subtotal — Carried Over From Base | E15: =SUM(E6:E14) -> 4965
A16: CARRIED OVER FROM PREMIUM — all Premium work is included
A17: 10 | B17: Electronics - Pumps | C17: Pump Replacement ($650 per pump) | D17: ALL pumps — no per-pump upcharge | E17: 1300
A18: 11 | B18: Electronics - Lighting | C18: LED Lighting Upgrade (x16 Sloan modules) | D18: Included — Upgrade | E18: 1360
A19: 12 | B19: Shell-Mounted | C19: Shell-Mounted Component Replacement | D19: Included — Upgrade | E19: 920
A20: 13 | B20: Cleaning | C20: Shell Polishing | D20: Included — Upgrade | E20: 620
A21: 14 | B21: Refined Hardware | C21: Hardware Refinishing | D21: Included — Upgrade | E21: 500
A22: 15 | B22: Trim / Accessories | C22: Side Paint & Varnish | D22: Included — Upgrade | E22: 351
A23: 16 | B23: Water Care | C23: FROG Water-Care System | D23: Included — Upgrade | E23: 350
A24: 17 | B24: Upgrades | C24: Rodent Protection Package | D24: Included | E24: 600
A25: 18 | B25: Service | C25: Spa Care Subscription (per month) | D25: First 3 months included | E25: 708
D26: Subtotal — Carried Over From Premium | E26: =SUM(E17:E25) -> 6709
A27: ADDED AT PLATINUM — exclusive to this package
A28: 19 | B28: Electronics - Controller | C28: Topside Controller Upgrade (Balboa SpaTouch4 Wi-Fi) | D28: Included — Platinum Exclusive | E28: 800
A29: 20 | B29: Electronics - Spa Pack | C29: Spa Pack Upgrade (Balboa BP7, 4.0/5.5 kW) | D29: Included — Platinum Exclusive | E29: 750
A30: 21 | B30: Electronics - Audio | C30: Stereo Upgrade (marine-grade + subwoofer) | D30: Included — Platinum Exclusive | E30: 1368
A31: 22 | B31: Electronics - Pumps | C31: Circulation Pump Installation | D31: Included — Platinum Exclusive | E31: 400
A32: 23 | B32: Cover | C32: Custom Spa Cover (double 4 mm vapor barrier) | D32: Included — Platinum Exclusive | E32: 890
A33: 24 | B33: Warranty | C33: Extended Warranty Upgrade (1 year vs 90 days) | D33: Included — Platinum Exclusive | E33: 150
D34: Subtotal — Added At Platinum | E34: =SUM(E28:E33) -> 4358
D36: PRICE WITHOUT THE RESTORATION PACKAGE | E36: ='Package Comparison'!J36 -> 16032
D37: PRICE WITH THE RESTORATION PACKAGE | E37: ='Package Comparison'!J40 -> 8400
C38: ="("&TEXT('Package Comparison'!J42,"0%")&" off the without-package price)" -> (48% off the without-package price) | D38: YOU SAVE | E38: ='Package Comparison'!J41 -> 7632
D39: Warranty | E39: 1 year
D40: Round-trip transportation | E40: Included

Sheet Individual Price List
A1: INDIVIDUAL SHOP PRICING — PRICES WITHOUT A PACKAGE
A2: What each job costs on its own, with the full customer-facing description.
A4: Category | B4: Line Item | C4: Shop Price | D4: Job Description
A5: Structural & Frame | B5: Frame Repair | C5: 900 | D5: Replace rotten frame boards with pressure-treated lumber and coat replacement boards in gloss black, water-resistant paint.
A6: Electronics - Pumps | B6: Pump Rebuild | C6: 360 | D6: Rebuild all pumps in the spa, including replacement of both motor bearings, ceramic shaft seal and wet-end O-rings, followed by electrical bench testing at 120V/240V and 45 PSI water-pressure testing.
A7: Electronics - Pumps | B7: Pump Replacement ($650 per pump) | C7: 650 | D7: Replace spa pumps with new pumps. Premium includes one pump and quotes $650 for each additional pump; Platinum replaces every pump in the spa with no per-pump upcharge.
A8: Electronics - Other | B8: Ozone Generator Installation | C8: 255 | D8: Remove existing unit if applicable, install and secure new ozone generator, connect air line and check valve, complete electrical connections, and test operation and ozone delivery.
A9: Cleaning | B9: Internal Plumbing Chemical Flush | C9: 450 | D9: Perform a high-pressure chemical flush to break down buildup and dead skin, kill mold, and clean the inside of the plumbing system.
A10: Plumbing | B10: Plumbing Pressure Test (45 PSI) | C10: 1200 | D10: Remove jet inserts, plug jet openings with expansion plugs, pressurize plumbing to 45 PSI, inspect for leaks, and address identified leaks for a leak-free return.
A11: Jets | B11: Jet Resealing | C11: 105 | D11: Reseal leaking jet bodies as required.
A12: Trim / Accessories | B12: Headrest Replacement | C12: 45 | D12: Replace spa headrests if replacements are available for purchase.
A13: Upgrades | B13: Insulation Package | C13: 1000 | D13: Install insulation package.
A14: Logistics | B14: On-Prop Move with Two Hours | C14: 860 | D14: Transport hot tub from customer location to shop and return restored hot tub to customer.
A15: Electronics - Lighting | B15: LED Lighting Upgrade (x16 Sloan modules) | C15: 1360 | D15: Install LED lighting kit with (x16) 1-inch lenses and Sloan LED light modules.
A16: Shell-Mounted | B16: Shell-Mounted Component Replacement | C16: 920 | D16: Replace light lenses, waterfalls, and LED cup holders as applicable.
... A29: Warranty | B29: Extended Warranty Upgrade (1 year vs 90 days) | C29: 150 | D29: Extend the full-coverage restoration warranty from 90 days to a full year.
