Workbook

Sheet Summary
A1: 333 Toy Crawford Rd - 43x10 Elevated Sunroom Replacement: Demo, New Structure, Siding, Electrical, HVAC | J1: Project Totals
J2: Labor Cost | K2: =SUM(B11:B26) -> 16073.71
A3: Project | B3: 43x10 Elevated Sunroom Replace: New Posts/Beam/Floor/Walls, Vinyl Siding, 6 Windows, Mini-Split | J3: Material Cost | K3: =SUM(C11:C26) -> 19716.087
A4: Source Scope | B4: 333_Toy_Crawford_Sunroom_Scope.txt | J4: Equipment Cost | K4: =SUM(D11:D26) -> 1805
A5: Template Anchor | B5: Basement_Remodel_Breakdown_Locked_Template_v1.xlsx | J5: Grand Total | K5: =SUM(E11:E26) -> 37594.797
A6: Overall Footprint SF | B6: 430 | J6: Revenue: | K6: 66200
A7: Ceiling Height | B7: 8
A8: Note | B8: Use this workbook as a locked template. Populate detail rows only; preserve formulas, tabs, and section order. | J8: GP | K8: =K6-K5 -> 28605.203
J9: GP % | K9: =K8/K6 -> 0.43210276
A10: Section | B10: Labor Cost | C10: Material Cost | D10: Equipment Cost | E10: Section Total | F10: Labor Hours
A11: General Conditions, Temporary Shoring & Structural Support | B11: =SUMIF(Labor_Detail!$A:$A,A11,Labor_Detail!$E:$E) -> 1373.96 | C11: =SUMIF(Material_Detail!$A:$A,A11,Material_Detail!$H:$H) -> 1140 | D11: =SUMIF(Equipment_Detail!$A:$A,A11,Equipment_Detail!$F:$F) -> 0 | E11: =SUM(B11:D11) -> 2513.96 | F11: =SUMIF(Labor_Detail!$A:$A,A11,Labor_Detail!$C:$C) -> 36
A12: Selective Demo - 43x10 Elevated Sunroom to Bearing Points (3 Dump Runs) | B12: =SUMIF(Labor_Detail!$A:$A,A12,Labor_Detail!$E:$E) -> 1670 | C12: =SUMIF(Material_Detail!$A:$A,A12,Material_Detail!$H:$H) -> 1470 | D12: =SUMIF(Equipment_Detail!$A:$A,A12,Equipment_Detail!$F:$F) -> 1350 | E12: =SUM(B12:D12) -> 4490 | F12: =SUMIF(Labor_Detail!$A:$A,A12,Labor_Detail!$C:$C) -> 48
A13: Foundation - 8 Post Footers, Post Brackets & 3-Ply 2x12 Primary Beam 44 LF | B13: =SUMIF(Labor_Detail!$A:$A,A13,Labor_Detail!$E:$E) -> 1524.1 | C13: =SUMIF(Material_Detail!$A:$A,A13,Material_Detail!$H:$H) -> 2406.16 | D13: =SUMIF(Equipment_Detail!$A:$A,A13,Equipment_Detail!$F:$F) -> 95 | E13: =SUM(B13:D13) -> 4025.26 | F13: =SUMIF(Labor_Detail!$A:$A,A13,Labor_Detail!$C:$C) -> 44
A14: Floor System - PT Framing, Subfloor, Floor Insulation & Vinyl Soffit Below | B14: =SUMIF(Labor_Detail!$A:$A,A14,Labor_Detail!$E:$E) -> 2994.05 | C14: =SUMIF(Material_Detail!$A:$A,A14,Material_Detail!$H:$H) -> 3917.7 | D14: =SUMIF(Equipment_Detail!$A:$A,A14,Equipment_Detail!$F:$F) -> 360 | E14: =SUM(B14:D14) -> 7271.75 | F14: =SUMIF(Labor_Detail!$A:$A,A14,Labor_Detail!$C:$C) -> 87
A15: Wall Framing - 63 LF Exterior, Sheathing, WRB & Vinyl Siding | B15: =SUMIF(Labor_Detail!$A:$A,A15,Labor_Detail!$E:$E) -> 2382.95 | C15: =SUMIF(Material_Detail!$A:$A,A15,Material_Detail!$H:$H) -> 2475.75 | D15: =SUMIF(Equipment_Detail!$A:$A,A15,Equipment_Detail!$F:$F) -> 0 | E15: =SUM(B15:D15) -> 4858.7 | F15: =SUMIF(Labor_Detail!$A:$A,A15,Labor_Detail!$C:$C) -> 69
A16: Windows (6 x 36x60) & Exterior Pre-Hung Door (36x80) | B16: =SUMIF(Labor_Detail!$A:$A,A16,Labor_Detail!$E:$E) -> 665.25 | C16: =SUMIF(Material_Detail!$A:$A,A16,Material_Detail!$H:$H) -> 2450 | D16: =SUMIF(Equipment_Detail!$A:$A,A16,Equipment_Detail!$F:$F) -> 0 | E16: =SUM(B16:D16) -> 3115.25 | F16: =SUMIF(Labor_Detail!$A:$A,A16,Labor_Detail!$C:$C) -> 19
A17: Roof Integration - Reattach Shed Roof, Flashing & 2 Patch/Repairs | B17: =SUMIF(Labor_Detail!$A:$A,A17,Labor_Detail!$E:$E) -> 845.1 | C17: =SUMIF(Material_Detail!$A:$A,A17,Material_Detail!$H:$H) -> 407 | D17: =SUMIF(Equipment_Detail!$A:$A,A17,Equipment_Detail!$F:$F) -> 0 | E17: =SUM(B17:D17) -> 1252.1 | F17: =SUMIF(Labor_Detail!$A:$A,A17,Labor_Detail!$C:$C) -> 24
A18: Electrical - Disconnect to Subpanel, Outlets, 6 Fixtures, 2 Fans & Switches | B18: =SUMIF(Labor_Detail!$A:$A,A18,Labor_Detail!$E:$E) -> 1560 | C18: =SUMIF(Material_Detail!$A:$A,A18,Material_Detail!$H:$H) -> 1701.425 | D18: =SUMIF(Equipment_Detail!$A:$A,A18,Equipment_Detail!$F:$F) -> 0 | E18: =SUM(B18:D18) -> 3261.425 | F18: =SUMIF(Labor_Detail!$A:$A,A18,Labor_Detail!$C:$C) -> 40
A19: HVAC - Ductless Mini-Split $2,500 Allowance | B19: =SUMIF(Labor_Detail!$A:$A,A19,Labor_Detail!$E:$E) -> 390 | C19: =SUMIF(Material_Detail!$A:$A,A19,Material_Detail!$H:$H) -> 2645 | D19: =SUMIF(Equipment_Detail!$A:$A,A19,Equipment_Detail!$F:$F) -> 0 | E19: =SUM(B19:D19) -> 3035 | F19: =SUMIF(Labor_Detail!$A:$A,A19,Labor_Detail!$C:$C) -> 10
A20: Insulation - Exterior Wall Cavities (504 SF) & Floor Cavity (430 SF) | B20: =SUMIF(Labor_Detail!$A:$A,A20,Labor_Detail!$E:$E) -> 237.65 | C20: =SUMIF(Material_Detail!$A:$A,A20,Material_Detail!$H:$H) -> 356.552 | D20: =SUMIF(Equipment_Detail!$A:$A,A20,Equipment_Detail!$F:$F) -> 0 | E20: =SUM(B20:D20) -> 594.202 | F20: =SUMIF(Labor_Detail!$A:$A,A20,Labor_Detail!$C:$C) -> 7
A21: Drywall - Walls Only 848 SF, Level 3 Finish | B21: =SUMIF(Labor_Detail!$A:$A,A21,Labor_Detail!$E:$E) -> 2226.95 | C21: =SUMIF(Material_Detail!$A:$A,A21,Material_Detail!$H:$H) -> 701.5 | D21: =SUMIF(Equipment_Detail!$A:$A,A21,Equipment_Detail!$F:$F) -> 0 | E21: =SUM(B21:D21) -> 2928.45 | F21: =SUMIF(Labor_Detail!$A:$A,A21,Labor_Detail!$C:$C) -> 65
A22: Cleanup & Project Closeout | B22: =SUMIF(Labor_Detail!$A:$A,A22,Labor_Detail!$E:$E) -> 203.7 | C22: =SUMIF(Material_Detail!$A:$A,A22,Material_Detail!$H:$H) -> 45 | D22: =SUMIF(Equipment_Detail!$A:$A,A22,Equipment_Detail!$F:$F) -> 0 | E22: =SUM(B22:D22) -> 248.7 | F22: =SUMIF(Labor_Detail!$A:$A,A22,Labor_Detail!$C:$C) -> 6
... A26: Not Applicable | B26: =SUMIF(Labor_Detail!$A:$A,A26,Labor_Detail!$E:$E) -> 0 | C26: =SUMIF(Material_Detail!$A:$A,A26,Material_Detail!$H:$H) -> 0 | D26: =SUMIF(Equipment_Detail!$A:$A,A26,Equipment_Detail!$F:$F) -> 0 | E26: =SUM(B26:D26) -> 0 | F26: =SUMIF(Labor_Detail!$A:$A,A26,Labor_Detail!$C:$C) -> 0
A27: TOTALS | B27: =SUM(B11:B26) -> 16073.71 | C27: =SUM(C11:C26) -> 19716.087 | D27: =SUM(D11:D26) -> 1805 | E27: =SUM(E11:E26) -> 37594.797 | F27: =SUM(F11:F26) -> 455

Sheet Labor_Detail
A1: Section | B1: Trade Role | C1: Hours | D1: Rate | E1: Labor Cost | F1: Notes | G1: Rate Category
A2: General Conditions, Temporary Shoring & Structural Support | B2: Project Manager | C2: 8 | D2: {=IF(OR($A2="",$G2=""),"",_xlfn.XLOOKUP($G2,Labor_Rates!$A$3:$A$7,Labor_Rates!$B$3:$B$7))} -> 47.87 | E2: =IF(OR($A2="",$C2="",$D2=""),"",$C2*$D2) -> 382.96 | F2: Coordinate all work per IRC 2018 and NEC; verify existing electrical disconnect condition prior to reuse and modification; install jobsite protection at access points and adjacent finishes below work area; coordinate temporary shoring plan before any demolition begins; NOTE: all work sequence governed by shoring plan - shoring must be in place before any structural demolition | G2: Project Manager
A3: General Conditions, Temporary Shoring & Structural Support | B3: Team Lead | C3: 8 | D3: {=IF(OR($A3="",$G3=""),"",_xlfn.XLOOKUP($G3,Labor_Rates!$A$3:$A$7,Labor_Rates!$B$3:$B$7))} -> 39 | E3: =IF(OR($A3="",$C3="",$D3=""),"",$C3*$D3) -> 312 | F3: Install temporary shoring and structural support system to maintain existing shed roof during full demolition and reconstruction phases; shoring must be designed for 43-ft roof span and remain until new wall structure is fully framed, sheathed, and capable of carrying roof loads; install all jobsite protection along access paths and adjacent finished areas below | G3: Team Lead
A4: General Conditions, Temporary Shoring & Structural Support | B4: General Labor | C4: 20 | D4: {=IF(OR($A4="",$G4=""),"",_xlfn.XLOOKUP($G4,Labor_Rates!$A$3:$A$7,Labor_Rates!$B$3:$B$7))} -> 33.95 | E4: =IF(OR($A4="",$C4="",$D4=""),"",$C4*$D4) -> 679 | F4: Erect temporary shoring system - 43-ft roof span: install vertical shores, horizontal wales, and bracing as required; maintain and inspect shoring daily throughout demolition and rebuild; remove and dispose of shoring materials at project completion after roof is permanently secured | G4: General Labor
A5: Selective Demo - 43x10 Elevated Sunroom to Bearing Points (3 Dump Runs) | B5: Team Lead | C5: 8 | D5: {=IF(OR($A5="",$G5=""),"",_xlfn.XLOOKUP($G5,Labor_Rates!$A$3:$A$7,Labor_Rates!$B$3:$B$7))} -> 39 | E5: =IF(OR($A5="",$C5="",$D5=""),"",$C5*$D5) -> 312 | F5: Demo planning: confirm all bearing points before any cutting; coordinate demo sequence around active shoring; plan debris lowering method from elevated structure; 3 dump trailer runs budgeted per scope | G5: Team Lead
A6: Selective Demo - 43x10 Elevated Sunroom to Bearing Points (3 Dump Runs) | B6: General Labor | C6: 40 | D6: {=IF(OR($A6="",$G6=""),"",_xlfn.XLOOKUP($G6,Labor_Rates!$A$3:$A$7,Labor_Rates!$B$3:$B$7))} -> 33.95 | E6: =IF(OR($A6="",$C6="",$D6=""),"",$C6*$D6) -> 1358 | F6: Demolish existing 43x10 elevated sunroom down to bearing points required for new construction: remove existing 6x6 posts, floor framing, subfloor, wall framing, windows, and ceiling assemblies; remove all existing substandard structural components; preserve existing shed roof system with temporary shoring throughout; lower all demo debris from elevated structure to ground; 3 dump trailer runs for all demolition debris | G6: General Labor
A7: Foundation - 8 Post Footers, Post Brackets & 3-Ply 2x12 Primary Beam 44 LF | B7: Team Lead | C7: 6 | D7: {=IF(OR($A7="",$G7=""),"",_xlfn.XLOOKUP($G7,Labor_Rates!$A$3:$A$7,Labor_Rates!$B$3:$B$7))} -> 39 | E7: =IF(OR($A7="",$C7="",$D7=""),"",$C7*$D7) -> 234 | F7: Foundation coordination: confirm footer locations near existing pad; confirm post spacing for new primary beam and floor system loads; confirm post bracket alignment before concrete sets; plan 3-ply 2x12 beam construction and erection sequence | G7: Team Lead
A8: Foundation - 8 Post Footers, Post Brackets & 3-Ply 2x12 Primary Beam 44 LF | B8: General Labor | C8: 12 | D8: {=IF(OR($A8="",$G8=""),"",_xlfn.XLOOKUP($G8,Labor_Rates!$A$3:$A$7,Labor_Rates!$B$3:$B$7))} -> 33.95 | E8: =IF(OR($A8="",$C8="",$D8=""),"",$C8*$D8) -> 407.4 | F8: Cut and install concrete footers at each of 8 post locations near existing pad - 12"x12"x12" each (8 CF total); hand-mix bags practical for this footer size; allow cure before loading post brackets | G8: General Labor
A9: Foundation - 8 Post Footers, Post Brackets & 3-Ply 2x12 Primary Beam 44 LF | B9: General Labor | C9: 4 | D9: {=IF(OR($A9="",$G9=""),"",_xlfn.XLOOKUP($G9,Labor_Rates!$A$3:$A$7,Labor_Rates!$B$3:$B$7))} -> 33.95 | E9: =IF(OR($A9="",$C9="",$D9=""),"",$C9*$D9) -> 135.8 | F9: Install galvanized post brackets anchored to each footer after cure - 8 post bases; confirm alignment and elevation before proceeding to posts | G9: General Labor
A10: Foundation - 8 Post Footers, Post Brackets & 3-Ply 2x12 Primary Beam 44 LF | B10: General Labor | C10: 12 | D10: {=IF(OR($A10="",$G10=""),"",_xlfn.XLOOKUP($G10,Labor_Rates!$A$3:$A$7,Labor_Rates!$B$3:$B$7))} -> 33.95 | E10: =IF(OR($A10="",$C10="",$D10=""),"",$C10*$D10) -> 407.4 | F10: Install 8 new 6x6 pressure-treated posts on post brackets - 8 posts x 1.5 hrs each = 12 hrs; plumb, brace, and confirm height at each post before beam installation | G10: General Labor
A11: Foundation - 8 Post Footers, Post Brackets & 3-Ply 2x12 Primary Beam 44 LF | B11: General Labor | C11: 10 | D11: {=IF(OR($A11="",$G11=""),"",_xlfn.XLOOKUP($G11,Labor_Rates!$A$3:$A$7,Labor_Rates!$B$3:$B$7))} -> 33.95 | E11: =IF(OR($A11="",$C11="",$D11=""),"",$C11*$D11) -> 339.5 | F11: Build and install (1) primary beam approximately 44 LF consisting of 3-ply 2x12 dimensional lumber fastened per code; assemble plies, nail/bolt per IRC, set on post tops; all framing per IRC span tables and loading requirements | G11: General Labor
A12: Floor System - PT Framing, Subfloor, Floor Insulation & Vinyl Soffit Below | B12: Team Lead | C12: 8 | D12: {=IF(OR($A12="",$G12=""),"",_xlfn.XLOOKUP($G12,Labor_Rates!$A$3:$A$7,Labor_Rates!$B$3:$B$7))} -> 39 | E12: =IF(OR($A12="",$C12="",$D12=""),"",$C12*$D12) -> 312 | F12: Floor system coordination: confirm PT joist sizing per IRC for 10-ft span; plan vinyl soffit installation sequence beneath floor framing before joists are set; confirm subfloor adhesive and fastening requirements | G12: Team Lead
A13: Floor System - PT Framing, Subfloor, Floor Insulation & Vinyl Soffit Below | B13: General Labor | C13: 40 | D13: {=IF(OR($A13="",$G13=""),"",_xlfn.XLOOKUP($G13,Labor_Rates!$A$3:$A$7,Labor_Rates!$B$3:$B$7))} -> 33.95 | E13: =IF(OR($A13="",$C13="",$D13=""),"",$C13*$D13) -> 1358 | F13: Frame new floor system using PT framing lumber per IRC span requirements - 34 joists at 16" OC spanning 10 ft (43-ft length); install ledger boards, rim joists, blocking, and hangers; all framing elevated - allow additional time for staging and elevated work | G13: General Labor
... A40: Not Applicable | B40: General Labor | C40: 0 | D40: {=IF(OR($A40="",$G40=""),"",_xlfn.XLOOKUP($G40,Labor_Rates!$A$3:$A$7,Labor_Rates!$B$3:$B$7))} -> 33.95 | E40: =IF(OR($A40="",$C40="",$D40=""),"",$C40*$D40) -> 0 | F40: Not Applicable | G40: General Labor
D41: {=IF(OR($A41="",$G41=""),"",_xlfn.XLOOKUP($G41,Labor_Rates!$A$3:$A$7,Labor_Rates!$B$3:$B$7,""))} | E41: =IF(OR($A41="",$C41="",$D41=""),"",$C41*$D41)
D42: {=IF(OR($A42="",$G42=""),"",_xlfn.XLOOKUP($G42,Labor_Rates!$A$3:$A$7,Labor_Rates!$B$3:$B$7,""))} | E42: =IF(OR($A42="",$C42="",$D42=""),"",$C42*$D42)
D43: {=IF(OR($A43="",$G43=""),"",_xlfn.XLOOKUP($G43,Labor_Rates!$A$3:$A$7,Labor_Rates!$B$3:$B$7,""))} | E43: =IF(OR($A43="",$C43="",$D43=""),"",$C43*$D43)
D44: {=IF(OR($A44="",$G44=""),"",_xlfn.XLOOKUP($G44,Labor_Rates!$A$3:$A$7,Labor_Rates!$B$3:$B$7,""))} | E44: =IF(OR($A44="",$C44="",$D44=""),"",$C44*$D44)
D45: {=IF(OR($A45="",$G45=""),"",_xlfn.XLOOKUP($G45,Labor_Rates!$A$3:$A$7,Labor_Rates!$B$3:$B$7,""))} | E45: =IF(OR($A45="",$C45="",$D45=""),"",$C45*$D45)
D46: {=IF(OR($A46="",$G46=""),"",_xlfn.XLOOKUP($G46,Labor_Rates!$A$3:$A$7,Labor_Rates!$B$3:$B$7,""))} | E46: =IF(OR($A46="",$C46="",$D46=""),"",$C46*$D46)
D47: {=IF(OR($A47="",$G47=""),"",_xlfn.XLOOKUP($G47,Labor_Rates!$A$3:$A$7,Labor_Rates!$B$3:$B$7,""))} | E47: =IF(OR($A47="",$C47="",$D47=""),"",$C47*$D47)
D48: {=IF(OR($A48="",$G48=""),"",_xlfn.XLOOKUP($G48,Labor_Rates!$A$3:$A$7,Labor_Rates!$B$3:$B$7,""))} | E48: =IF(OR($A48="",$C48="",$D48=""),"",$C48*$D48)
D49: {=IF(OR($A49="",$G49=""),"",_xlfn.XLOOKUP($G49,Labor_Rates!$A$3:$A$7,Labor_Rates!$B$3:$B$7,""))} | E49: =IF(OR($A49="",$C49="",$D49=""),"",$C49*$D49)
D50: {=IF(OR($A50="",$G50=""),"",_xlfn.XLOOKUP($G50,Labor_Rates!$A$3:$A$7,Labor_Rates!$B$3:$B$7,""))} | E50: =IF(OR($A50="",$C50="",$D50=""),"",$C50*$D50)
D51: {=IF(OR($A51="",$G51=""),"",_xlfn.XLOOKUP($G51,Labor_Rates!$A$3:$A$7,Labor_Rates!$B$3:$B$7,""))} | E51: =IF(OR($A51="",$C51="",$D51=""),"",$C51*$D51)
D52: {=IF(OR($A52="",$G52=""),"",_xlfn.XLOOKUP($G52,Labor_Rates!$A$3:$A$7,Labor_Rates!$B$3:$B$7,""))} | E52: =IF(OR($A52="",$C52="",$D52=""),"",$C52*$D52)
... D300: {=IF(OR($A300="",$G300=""),"",_xlfn.XLOOKUP($G300,Labor_Rates!$A$3:$A$7,Labor_Rates!$B$3:$B$7,""))} | E300: =IF(OR($A300="",$C300="",$D300=""),"",$C300*$D300)

Sheet Material_Detail
A1: Section | B1: Material | C1: Description | D1: Quantity | E1: Unit | F1: Unit Cost | G1: Waste Factor | H1: Line Total | I1: Notes
A2: General Conditions, Temporary Shoring & Structural Support | B2: Project Consumables | C2: Caulk, fasteners, misc hardware | D2: 1 | E2: lot | F2: 280 | G2: 0 | H2: =IF(OR($A2="",$D2=""),"",$D2*$F2*(1+$G2)) -> 280
A3: General Conditions, Temporary Shoring & Structural Support | B3: Temporary Shoring Materials | C3: Vertical shores, horizontal wales, bracing for 43-ft roof span | D3: 1 | E3: lot | F3: 680 | G3: 0 | H3: =IF(OR($A3="",$D3=""),"",$D3*$F3*(1+$G3)) -> 680 | I3: Critical: must be designed for full roof load during demo and rebuild
A4: General Conditions, Temporary Shoring & Structural Support | B4: Jobsite Protection Materials | C4: Plywood, tarps, barriers at access and adjacent finishes below | D4: 1 | E4: lot | F4: 180 | G4: 0 | H4: =IF(OR($A4="",$D4=""),"",$D4*$F4*(1+$G4)) -> 180
A5: Selective Demo - 43x10 Elevated Sunroom to Bearing Points (3 Dump Runs) | B5: Demo Supplies | C5: Reciprocating blades, pry bars, demo bags, safety equipment | D5: 1 | E5: lot | F5: 120 | G5: 0 | H5: =IF(OR($A5="",$D5=""),"",$D5*$F5*(1+$G5)) -> 120
A6: Selective Demo - 43x10 Elevated Sunroom to Bearing Points (3 Dump Runs) | B6: Debris Disposal | C6: 3 dump trailer runs per scope | D6: 3 | E6: ea | F6: 450 | G6: 0 | H6: =IF(OR($A6="",$D6=""),"",$D6*$F6*(1+$G6)) -> 1350 | I6: Per scope
A7: Foundation - 8 Post Footers, Post Brackets & 3-Ply 2x12 Primary Beam 44 LF | B7: Concrete - Footers | C7: 8 footers at 12x12x12; hand-mix bags; 16 x 80-lb bags | D7: 16 | E7: bag | F7: 7.5 | G7: 0.05 | H7: =IF(OR($A7="",$D7=""),"",$D7*$F7*(1+$G7)) -> 126 | I7: Small footers - hand-mix more practical than ready-mix
A8: Foundation - 8 Post Footers, Post Brackets & 3-Ply 2x12 Primary Beam 44 LF | B8: Galvanized Post Brackets | C8: 8 post bases - galvanized | D8: 8 | E8: ea | F8: 32 | G8: 0 | H8: =IF(OR($A8="",$D8=""),"",$D8*$F8*(1+$G8)) -> 256
A9: Foundation - 8 Post Footers, Post Brackets & 3-Ply 2x12 Primary Beam 44 LF | B9: Anchor Hardware for Post Brackets | C9: Epoxy anchors or anchor bolts at each footer | D9: 8 | E9: set | F9: 14 | G9: 0 | H9: =IF(OR($A9="",$D9=""),"",$D9*$F9*(1+$G9)) -> 112
A10: Foundation - 8 Post Footers, Post Brackets & 3-Ply 2x12 Primary Beam 44 LF | B10: 6x6 PT Posts | C10: 8 posts at approximately 10 ft | D10: 8 | E10: ea | F10: 85 | G10: 0.05 | H10: =IF(OR($A10="",$D10=""),"",$D10*$F10*(1+$G10)) -> 714
A11: Foundation - 8 Post Footers, Post Brackets & 3-Ply 2x12 Primary Beam 44 LF | B11: 2x12 Dimensional Lumber - Primary Beam | C11: 132 LF of 2x12 for 3-ply x 44 LF beam | D11: 132 | E11: lf | F11: 5.8 | G11: 0.1 | H11: =IF(OR($A11="",$D11=""),"",$D11*$F11*(1+$G11)) -> 842.16
A12: Foundation - 8 Post Footers, Post Brackets & 3-Ply 2x12 Primary Beam 44 LF | B12: Beam Connection Hardware | C12: Through-bolts, structural screws, bearing plates for 3-ply beam | D12: 1 | E12: lot | F12: 180 | G12: 0 | H12: =IF(OR($A12="",$D12=""),"",$D12*$F12*(1+$G12)) -> 180
A13: Foundation - 8 Post Footers, Post Brackets & 3-Ply 2x12 Primary Beam 44 LF | B13: Post Caps + Structural Hardware | C13: Post-to-beam connectors and structural ties | D13: 8 | E13: ea | F13: 22 | G13: 0 | H13: =IF(OR($A13="",$D13=""),"",$D13*$F13*(1+$G13)) -> 176
A14: Floor System - PT Framing, Subfloor, Floor Insulation & Vinyl Soffit Below | B14: PT Floor Joists | C14: 34 joists spanning 10 ft - sized per IRC span | D14: 34 | E14: ea | F14: 42 | G14: 0.05 | H14: =IF(OR($A14="",$D14=""),"",$D14*$F14*(1+$G14)) -> 1499.4
A15: Floor System - PT Framing, Subfloor, Floor Insulation & Vinyl Soffit Below | B15: PT Rim Joists and Ledger | C15: Perimeter framing: 2x{D}+2x{W} = ~106 LF | D15: 1 | E15: lot | F15: 380 | G15: 0.1 | H15: =IF(OR($A15="",$D15=""),"",$D15*$F15*(1+$G15)) -> 418
A16: Floor System - PT Framing, Subfloor, Floor Insulation & Vinyl Soffit Below | B16: Joist Hangers | C16: At all joist-to-ledger and joist-to-beam connections | D16: 34 | E16: ea | F16: 2.8 | G16: 0.05 | H16: =IF(OR($A16="",$D16=""),"",$D16*$F16*(1+$G16)) -> 99.96
A17: Floor System - PT Framing, Subfloor, Floor Insulation & Vinyl Soffit Below | B17: Subfloor Sheathing 3/4 in T&G | C17: 15 sheets glued and fastened | D17: 15 | E17: sheet | F17: 62 | G17: 0.05 | H17: =IF(OR($A17="",$D17=""),"",$D17*$F17*(1+$G17)) -> 976.5
A18: Floor System - PT Framing, Subfloor, Floor Insulation & Vinyl Soffit Below | B18: Subfloor Adhesive | C18: PL400 construction adhesive | D18: 4 | E18: ea | F18: 8 | G18: 0 | H18: =IF(OR($A18="",$D18=""),"",$D18*$F18*(1+$G18)) -> 32
A19: Floor System - PT Framing, Subfloor, Floor Insulation & Vinyl Soffit Below | B19: Floor Batt Insulation | C19: 430 SF in floor cavity | D19: 430 | E19: sf | F19: 0.58 | G19: 0.1 | H19: =IF(OR($A19="",$D19=""),"",$D19*$F19*(1+$G19)) -> 274.34
A20: Floor System - PT Framing, Subfloor, Floor Insulation & Vinyl Soffit Below | B20: Vinyl Soffit - Below Floor | C20: 5 squares under floor framing | D20: 5 | E20: sq | F20: 95 | G20: 0.1 | H20: =IF(OR($A20="",$D20=""),"",$D20*$F20*(1+$G20)) -> 522.5 | I20: Weather and pest protection below floor structure
A21: Floor System - PT Framing, Subfloor, Floor Insulation & Vinyl Soffit Below | B21: Soffit Accessories | C21: J-channel, F-channel, vents, fasteners for floor soffit | D21: 1 | E21: lot | F21: 95 | G21: 0 | H21: =IF(OR($A21="",$D21=""),"",$D21*$F21*(1+$G21)) -> 95
A22: Wall Framing - 63 LF Exterior, Sheathing, WRB & Vinyl Siding | B22: 2x4 Wall Studs | C22: 52 studs for 63 LF walls | D22: 52 | E22: ea | F22: 6.5 | G22: 0.1 | H22: =IF(OR($A22="",$D22=""),"",$D22*$F22*(1+$G22)) -> 371.8
A23: Wall Framing - 63 LF Exterior, Sheathing, WRB & Vinyl Siding | B23: 2x4 Wall Plates | C23: 24 pcs - 63 LF x 3 | D23: 24 | E23: ea | F23: 6.5 | G23: 0.1 | H23: =IF(OR($A23="",$D23=""),"",$D23*$F23*(1+$G23)) -> 171.6
A24: Wall Framing - 63 LF Exterior, Sheathing, WRB & Vinyl Siding | B24: Window Headers and Blocking | C24: LVL or built-up headers at 6 window openings | D24: 1 | E24: lot | F24: 180 | G24: 0.1 | H24: =IF(OR($A24="",$D24=""),"",$D24*$F24*(1+$G24)) -> 198
A25: Wall Framing - 63 LF Exterior, Sheathing, WRB & Vinyl Siding | B25: Door Header and Blocking | C25: Header at 36-in door opening | D25: 1 | E25: ea | F25: 55 | G25: 0.05 | H25: =IF(OR($A25="",$D25=""),"",$D25*$F25*(1+$G25)) -> 57.75
A26: Wall Framing - 63 LF Exterior, Sheathing, WRB & Vinyl Siding | B26: Wall Sheathing 7/16 in OSB | C26: 18 sheets exterior walls | D26: 18 | E26: sheet | F26: 22 | G26: 0.1 | H26: =IF(OR($A26="",$D26=""),"",$D26*$F26*(1+$G26)) -> 435.6
A27: Wall Framing - 63 LF Exterior, Sheathing, WRB & Vinyl Siding | B27: House Wrap WRB | C27: Weather-resistant barrier full wall area | D27: 1 | E27: lot | F27: 95 | G27: 0 | H27: =IF(OR($A27="",$D27=""),"",$D27*$F27*(1+$G27)) -> 95
A28: Wall Framing - 63 LF Exterior, Sheathing, WRB & Vinyl Siding | B28: WRB Tape and Accessories | C28: Seam tape, window integration tape | D28: 1 | E28: lot | F28: 45 | G28: 0 | H28: =IF(OR($A28="",$D28=""),"",$D28*$F28*(1+$G28)) -> 45
A29: Wall Framing - 63 LF Exterior, Sheathing, WRB & Vinyl Siding | B29: Vinyl Lap Siding (allowance) | C29: 5 squares at $150/sq retail | D29: 5 | E29: sq | F29: 150 | G29: 0.1 | H29: =IF(OR($A29="",$D29=""),"",$D29*$F29*(1+$G29)) -> 825 | I29: Allowance per scope
A30: Wall Framing - 63 LF Exterior, Sheathing, WRB & Vinyl Siding | B30: Siding Accessories | C30: Starter strip, J-channel, corner posts, utility trim | D30: 1 | E30: lot | F30: 120 | G30: 0 | H30: =IF(OR($A30="",$D30=""),"",$D30*$F30*(1+$G30)) -> 120
A31: Wall Framing - 63 LF Exterior, Sheathing, WRB & Vinyl Siding | B31: Exterior Trim | C31: Corner boards, window and door surround trim | D31: 1 | E31: lot | F31: 120 | G31: 0.1 | H31: =IF(OR($A31="",$D31=""),"",$D31*$F31*(1+$G31)) -> 132
A32: Wall Framing - 63 LF Exterior, Sheathing, WRB & Vinyl Siding | B32: Exterior Caulk | C32: All siding transitions and penetrations | D32: 3 | E32: ea | F32: 8 | G32: 0 | H32: =IF(OR($A32="",$D32=""),"",$D32*$F32*(1+$G32)) -> 24
A33: Windows (6 x 36x60) & Exterior Pre-Hung Door (36x80) | B33: Vinyl Windows 36x60 (allowance) | C33: 6 at $300 each retail | D33: 6 | E33: ea | F33: 300 | G33: 0 | H33: =IF(OR($A33="",$D33=""),"",$D33*$F33*(1+$G33)) -> 1800 | I33: Allowance per scope
A34: Windows (6 x 36x60) & Exterior Pre-Hung Door (36x80) | B34: Exterior Door 36x80 (allowance) | C34: $500 retail with hardware | D34: 1 | E34: ea | F34: 500 | G34: 0 | H34: =IF(OR($A34="",$D34=""),"",$D34*$F34*(1+$G34)) -> 500 | I34: Allowance per scope
A35: Windows (6 x 36x60) & Exterior Pre-Hung Door (36x80) | B35: Window Install Materials | C35: Flashing tape, foam, sill pan, exterior caulk at 6 windows | D35: 1 | E35: lot | F35: 95 | G35: 0 | H35: =IF(OR($A35="",$D35=""),"",$D35*$F35*(1+$G35)) -> 95
A36: Windows (6 x 36x60) & Exterior Pre-Hung Door (36x80) | B36: Door Install Materials | C36: Flashing tape, foam, threshold, sill pan | D36: 1 | E36: lot | F36: 55 | G36: 0 | H36: =IF(OR($A36="",$D36=""),"",$D36*$F36*(1+$G36)) -> 55
A37: Roof Integration - Reattach Shed Roof, Flashing & 2 Patch/Repairs | B37: Roof-to-Wall Flashing | C37: Step flashing, counter flashing, and cap flashing at roof tie-in | D37: 1 | E37: lot | F37: 220 | G37: 0.1 | H37: =IF(OR($A37="",$D37=""),"",$D37*$F37*(1+$G37)) -> 242
A38: Roof Integration - Reattach Shed Roof, Flashing & 2 Patch/Repairs | B38: Roof Patch Materials | C38: Shingles and materials for 2 patch/repairs at old vent locations | D38: 1 | E38: lot | F38: 120 | G38: 0 | H38: =IF(OR($A38="",$D38=""),"",$D38*$F38*(1+$G38)) -> 120 | I38: Match existing shingle as closely as possible
A39: Roof Integration - Reattach Shed Roof, Flashing & 2 Patch/Repairs | B39: Roofing Sealant | C39: Lap cement, silicone at all flashing transitions | D39: 1 | E39: lot | F39: 45 | G39: 0 | H39: =IF(OR($A39="",$D39=""),"",$D39*$F39*(1+$G39)) -> 45
A40: Electrical - Disconnect to Subpanel, Outlets, 6 Fixtures, 2 Fans & Switches | B40: Electrical Panel Conversion Kit | C40: Breaker kit to convert existing fuse disconnect to breaker subpanel | D40: 1 | E40: lot | F40: 180 | G40: 0 | H40: =IF(OR($A40="",$D40=""),"",$D40*$F40*(1+$G40)) -> 180
...

Sheet Equipment_Detail
A1: Section | B1: Equipment or Misc Item | C1: Quantity | D1: Unit | E1: Unit Cost | F1: Line Total | G1: Notes
A2: Selective Demo - 43x10 Elevated Sunroom to Bearing Points (3 Dump Runs) | B2: Dumpster - 3 Runs | C2: 3 | D2: ea | E2: 450 | F2: =IF(OR($A2="",$C2=""),"",$C2*$E2) -> 1350 | G2: 3 runs per scope
A3: Foundation - 8 Post Footers, Post Brackets & 3-Ply 2x12 Primary Beam 44 LF | B3: Concrete Mixer - Footers | C3: 1 | D3: day | E3: 95 | F3: =IF(OR($A3="",$C3=""),"",$C3*$E3) -> 95 | G3: Hand-mix footers on-site
A4: Floor System - PT Framing, Subfloor, Floor Insulation & Vinyl Soffit Below | B4: Scaffolding - Elevated Floor Work | C4: 2 | D4: day | E4: 180 | F4: =IF(OR($A4="",$C4=""),"",$C4*$E4) -> 360 | G4: Elevated floor framing and soffit install
F5: =IF(OR($A5="",$C5="",$E5=""),"",$C5*$E5)
F6: =IF(OR($A6="",$C6="",$E6=""),"",$C6*$E6)
F7: =IF(OR($A7="",$C7="",$E7=""),"",$C7*$E7)
F8: =IF(OR($A8="",$C8="",$E8=""),"",$C8*$E8)
F9: =IF(OR($A9="",$C9="",$E9=""),"",$C9*$E9)
F10: =IF(OR($A10="",$C10="",$E10=""),"",$C10*$E10)
F11: =IF(OR($A11="",$C11="",$E11=""),"",$C11*$E11)
F12: =IF(OR($A12="",$C12="",$E12=""),"",$C12*$E12)
F13: =IF(OR($A13="",$C13="",$E13=""),"",$C13*$E13)
F14: =IF(OR($A14="",$C14="",$E14=""),"",$C14*$E14)
F15: =IF(OR($A15="",$C15="",$E15=""),"",$C15*$E15)
F16: =IF(OR($A16="",$C16="",$E16=""),"",$C16*$E16)
... F200: =IF(OR($A200="",$C200="",$E200=""),"",$C200*$E200)

Sheet PM_Notes
A1: Section | B1: Risk Type | C1: Issue | D1: PM Recommendation
A2: CRITICAL - Temporary Shoring Must Be In Place Before Any Demo | B2: Safety/Structural | C2: The existing shed roof must be continuously supported by a temporary shoring system before any structural demolition begins. This is the highest risk item on this project. The shoring system must be designed to carry the full roof load at a 43-ft span. Shoring must remain active until the new wall structure is fully framed, sheathed, and the roof is permanently reseated and flashed. | D2: Design shoring plan before mobilizing. Install all shoring before touching any existing structural component. Inspect shoring daily. Do not remove shoring until TL confirms new walls are fully capable of carrying roof load. Roof integration and final flashing must be complete before shoring is removed.
A3: Existing Disconnect Panel Condition - Verify Before Modification | B3: Electrical Risk | C3: Scope requires modifying the existing disconnect panel by replacing fuses with breakers to function as a subpanel. The condition of the existing panel must be verified before any modification. If the panel is deteriorated, unsafe, or not suitable for conversion, a new subpanel may be required at additional cost. | D3: Electrician must assess existing disconnect panel condition before ordering breaker conversion kit. If panel enclosure, bus, or wiring is unsuitable, present replacement cost to customer. Verify existing panel can legally serve as subpanel in this jurisdiction.
A4: Substandard Original Construction - Unknown Hidden Conditions | B4: Production Risk | C4: This project is replacing a structure that had improper original construction. Additional hidden structural deficiencies, non-code conditions, or connection issues may be discovered during demolition that are not visible before work begins. | D4: Document all conditions discovered during demolition with photos. Stop and present any discovered structural issues to customer before proceeding. Any required correction of conditions outside the written scope = change order.
A5: Roof Reintegration - Weather Exposure During Construction | B5: Production Risk | C5: Reintegrating the existing shed roof onto new walls creates a period of weather exposure. The transition from demolition to new wall framing to roof reseating must be coordinated with favorable weather. Emergency tarping must be on-site throughout the project. | D5: Monitor weather forecast continuously during the demo and rebuild phase. Have tarps and fasteners staged on-site before demo begins. Plan roof reseating work to be completed in one continuous work session when possible. Do not leave roof open overnight without temporary weather protection.
A6: Vinyl Soffit Under Floor - Overhead Work | B6: Production Risk | C6: 430 SF of vinyl soffit installed below the elevated floor framing is significant overhead work. This requires scaffolding or staging below the structure and is more labor-intensive than standard soffit work. | D6: Confirm scaffolding is staged below floor before floor framing begins. Plan soffit installation immediately after floor framing and before subfloor is installed if access from above is possible. If installed from below, rolling scaffold is required.

Sheet Assumptions
A1: Category
A2: Project name | B2: 333 Toy Crawford Rd - 43x10 Elevated Sunroom Replacement | D2: From scope / intake | E2: Metadata
A3: Overall footprint | B3: 430 | C3: SF | D3: From intake and scope | E3: Drives flooring, ceiling, production
A4: Ceiling height | B4: 8 | C4: ft | D4: From intake and scope | E4: Drives wall area
A5: Interior wall length | B5: 8 | C5: LF | D5: From intake/drawings or assumptions | E5: Drives framing and two-sided finishes
A6: Structure | B6: 43x10 = 430 SF elevated second-story sunroom replacement | C6: SF | D6: Full demo + rebuild | E6: Drives framing, insulation, one-sided finishes | F6: Existing shed roof preserved throughout via shoring
A7: Shoring | B7: 43-ft roof span temporary support | D7: Must be in place before any demo | E7: Drives drywall, paint | F7: Critical: do not demo without shoring
A8: Foundation | B8: 8 x 6x6 PT posts on 12x12x12 footers | C8: ea | D8: Post brackets after footer cure | E8: Drives trim | F8: Small footers - hand-mix bags
A9: Primary Beam | B9: 3-ply 2x12 x 44 LF = 132 LF of 2x12 | C9: LF | D9: Per IRC span tables | E9: Drives trim and CO logic
A10: Floor | B10: 34 PT joists 10-ft span; 15 sh subfloor; 430 SF insulation | C10: SF | D10: PT framing throughout | E10: Scope alignment | F10: 430 SF vinyl soffit below floor (5 squares)
A11: Walls | B11: 63 LF ext walls (3 sides); sheathing + WRB + vinyl siding | C11: LF | D11: House side = roof integration only | E11: Scope alignment | F11: 5 squares vinyl siding at $150/sq allowance
A12: Windows | B12: 6 x 36x60 vinyl at $300 each + 1 door at $500 | C12: ea | D12: All allowances per scope | E12: Scope alignment | F12: Confirm availability before ordering
A13: Electrical | B13: Fuse-to-breaker panel conversion + outlets + 6 fixtures + 2 fans | C13: lot | D13: NEC compliant | E13: Drives tile materials and labor | F13: Verify existing panel condition first
A14: HVAC | B14: 1-zone mini-split $2,500 allowance | C14: ea | D14: 430 SF space | E14: Labor realism | F14: Confirm BTU sizing
A15: Drywall | B15: 848 SF walls only - no ceiling drywall per scope | C15: SF | D15: Level 3 finish | E15: Audit trail | F15: Ceiling drywall not in scope
A16: Insulation | B16: 504 SF wall cavities + 430 SF floor = 934 SF total | C16: SF | D16: R-13 batt throughout
A17: Total Labor Hrs | B17: ~455 | C17: hrs | D17: All sections combined | F17: See Labor_Detail for breakdown
A18: Sell Price | B18: $66,700 per previous scope | F18: Cost basis shown in workbook

Sheet Labor_Rates
A1: Editable Labor Rates
A2: Rate Category | B2: Hourly Rate | C2: Used For | D2: Note
A3: General Labor | B3: 33.95 | C3: Laborer, Carpenter, Painter, Drywall, Flooring, Tile, Cabinet install, countertop/template support | D3: Edit B3 only
A4: Team Lead | B4: 39 | C4: Any row marked Team Lead | D4: Edit B4 only
A5: Electrical/HVAC | B5: 39 | C5: Electrician, HVAC Tech, HVAC Helper | D5: Edit B5 only
A6: Plumbing | B6: 33.92 | C6: Plumber | D6: Edit B6 only
A7: Project Manager | B7: 47.87 | C7: Project Manager rows | D7: Edit B7 only
A9: Instructions | B9: Change any rate in column B and all linked labor rows plus summary labor totals will update.
A10: Example | B10: Set General Labor to 42 to update all General Labor rows everywhere in the workbook.

Sheet Template_Guide
A1: Locked Template Guide
A2: Purpose | B2: Use this exact workbook as the anchor template for every basement remodel output.
A3: How to use | B3: 1) Upload this template 2) Upload PM intake/validation workbook 3) Upload scope PDF 4) Upload locked prompt 5) Ask AI to populate THIS workbook only.
A4: Hard rules | B4: Do not rename tabs, do not change summary layout, do not hardcode totals, do not remove labor rate controls.
A5: Auto-create sections | B5: AI must map scope items into the standard sections listed on Section_Master. Unused sections stay in Summary with zero totals; detail tabs only get rows for relevant sections.
A6: Dropdowns | B6: Detail tabs use dropdown lists for Section, Rate Category, Risk Type, and common Units to keep data normalized.
A7: Change order logic | B7: Use PM intake scope-alignment flags to note credit opportunities and change-order risks in PM_Notes.
A8: Best practice | B8: Always upload this template with the prompt so the AI can match structure, formulas, and layout instead of improvising.

Sheet Data_Lists
A1: Sections | B1: Rate Categories | C1: Risk Types | D1: Units | E1: Include?
A2: General Conditions & Project Management | B2: General Labor | C2: Scope Gap | D2: ea | E2: Yes
A3: Selective Demolition | B3: Team Lead | C3: Change Order Risk | D3: lf | E3: No
A4: Framing | B4: Electrical/HVAC | C4: Credit Opportunity | D4: sf
A5: Windows & Exterior Openings | B5: Plumbing | C5: Existing Conditions | D5: sheet
A6: Plumbing & Waste Pump System | B6: Project Manager | C6: Takeoff Assumption | D6: lot
A7: Electrical | C7: Structural Risk | D7: gal
A8: HVAC - 3 Zone Mini Split | C8: Coordination | D8: bag
A9: Insulation & Air Sealing | C9: Sequencing | D9: box
A10: Drywall & Finishing | C10: Production Risk | D10: roll
A11: Suspended Ceiling System | C11: Allowance Risk | D11: set
A12: Interior Doors, Trim & Hardware | D12: pair
A13: Flooring | D13: day
A14: Painting
A15: Master Bathroom
A16: Kitchen
A17: Cleanup & Closeout

Sheet Section_Master
A1: Standard Section | B1: Default Include | C1: Use For / Notes
A2: General Conditions & Project Management | B2: Yes | C2: Site setup, PM time, scheduling, protection
A3: Selective Demolition | B3: Yes | C3: Selective demo, removals, disposal, concrete sawcut
A4: Framing | B4: Yes | C4: Exterior/interior walls, soffits, chases, blocking
A5: Windows & Exterior Openings | B5: Yes | C5: New windows, exterior doors, lintels, flashing
A6: Plumbing & Waste Pump System | B6: Yes | C6: Bath, kitchen, laundry, below-slab, ejector/pump
A7: Electrical | B7: Yes | C7: Subpanel, branch circuits, lighting, devices
A8: HVAC - 3 Zone Mini Split | B8: Yes | C8: Mini split or other HVAC equipment and startup
A9: Insulation & Air Sealing | B9: Yes | C9: Batt, foam, air sealing, sound attenuation
A10: Drywall & Finishing | B10: Yes | C10: Wall board, taping, mud, sanding, access panels
A11: Suspended Ceiling System | B11: Yes | C11: Drop ceiling grid, tile, access coordination
A12: Interior Doors, Trim & Hardware | B12: Yes | C12: Interior doors, base, casing, hardware, trim
... A17: Cleanup & Closeout | B17: Yes | C17: Final clean, punch support, closeout
